package com.hbm.datagen.worldgen.structure;

import com.hbm.blocks.ModBlocks;
import net.minecraft.core.Direction;
import net.minecraft.util.RandomSource;
import net.minecraft.world.level.WorldGenLevel;
import net.minecraft.world.level.block.*;
import net.minecraft.world.level.block.state.properties.AttachFace;
import net.minecraft.world.level.block.state.properties.BlockStateProperties;
import net.minecraft.world.level.block.state.properties.DoubleBlockHalf;
import net.minecraft.world.level.block.state.properties.Half;

public class Ruin001 extends BaseRuinGenerator {

    public void generate(WorldGenLevel level, int chunkX, int chunkZ, RandomSource rand) {
        this.level = level;
        this.rand = rand;

        // Ищем подходящую поверхность в центре чанка
        int x = chunkX * 16 + 8;
        int z = chunkZ * 16 + 8;
        int y = getSurfaceY(x, z);

        this.originX = x;
        this.originY = y;
        this.originZ = z;

        generate_r0();
        generate_r1();
        generate_r2();
        generate_r3();

    }

    public void generate_r0() {
        int x = originX;
        int y = originY;
        int z = originZ;

        // ===== Y + 0 =====
        setBlock(x + 1, y, z + 5, CONCRETE);
        setBlock(x + 1, y, z + 6, CONCRETE);
        setBlock(x + 2, y, z + 6, CONCRETE);
        setBlock(x + 3, y, z + 6, CONCRETE);
        setBlock(x + 4, y, z + 6, CONCRETE);
        setBlock(x + 5, y, z + 6, CONCRETE);
        setBlock(x + 6, y, z + 6, CONCRETE);
        setBlock(x + 7, y, z + 6, CONCRETE);
        setBlock(x + 8, y, z + 6, CONCRETE);
        setBlock(x + 3, y, z + 7, CONCRETE);
        setBlock(x + 1, y, z + 8, CONCRETE);
        setBlock(x + 2, y, z + 8, CONCRETE);
        setBlock(x + 3, y, z + 8, CONCRETE);
        setBlock(x + 1, y, z + 9, Blocks.FURNACE.defaultBlockState().setValue(FurnaceBlock.FACING, Direction.WEST));
        setBlock(x + 2, y, z + 9, CONCRETE);
        setBlock(x + 1, y, z + 10, CONCRETE);

        // ===== Y + 1 =====
        setBlock(x + 1, y + 1, z + 4, CONCRETE);
        setBlock(x, y + 1, z + 5, CONCRETE);
        setBlock(x + 1, y + 1, z + 5, Blocks.VINE.defaultBlockState());
        setBlock(x + 2, y + 1, z + 5, CONCRETE);
        setBlock(x + 3, y + 1, z + 5, CONCRETE);
        setBlock(x + 4, y + 1, z + 5, CONCRETE);
        setBlock(x + 5, y + 1, z + 5, CONCRETE);
        setBlock(x + 6, y + 1, z + 5, CONCRETE);
        setBlock(x + 7, y + 1, z + 5, CONCRETE);
        setBlock(x + 8, y + 1, z + 5, CONCRETE);
        setBlock(x, y + 1, z + 6, CONCRETE);
        setBlock(x + 9, y + 1, z + 6, CONCRETE);
        setBlock(x + 1, y + 1, z + 7, CONCRETE);
        setBlock(x + 2, y + 1, z + 7, CONCRETE);
        setBlock(x + 3, y + 1, z + 7, Blocks.VINE.defaultBlockState());
        setBlock(x + 4, y + 1, z + 7, CONCRETE);
        setBlock(x + 5, y + 1, z + 7, CONCRETE);
        setBlock(x + 6, y + 1, z + 7, CONCRETE);
        setBlock(x + 7, y + 1, z + 7, CONCRETE);
        setBlock(x + 8, y + 1, z + 7, CONCRETE);
        setBlock(x, y + 1, z + 8, CONCRETE);
        setBlock(x + 1, y + 1, z + 8, Blocks.VINE.defaultBlockState());
        setBlock(x + 2, y + 1, z + 8, Blocks.VINE.defaultBlockState());
        setBlock(x + 3, y + 1, z + 8, Blocks.VINE.defaultBlockState());
        setBlock(x + 4, y + 1, z + 8, CONCRETE);
        setBlock(x, y + 1, z + 9, CONCRETE);
        setBlock(x + 1, y + 1, z + 9, Blocks.VINE.defaultBlockState());
        setBlock(x + 2, y + 1, z + 9, Blocks.WATER.defaultBlockState());
        setBlock(x + 3, y + 1, z + 9, CONCRETE);
        setBlock(x, y + 1, z + 10, CONCRETE);
        setBlock(x + 1, y + 1, z + 10, Blocks.VINE.defaultBlockState());
        setBlock(x + 2, y + 1, z + 10, CONCRETE);
        setBlock(x + 1, y + 1, z + 11, CONCRETE);

        // ===== Y + 2 — начало =====
        setBlock(x + 1, y + 2, z + 4, CONCRETE);
        setBlock(x, y + 2, z + 5, CONCRETE);
        setBlock(x + 1, y + 2, z + 5, Blocks.VINE.defaultBlockState());
        setBlock(x + 2, y + 2, z + 5, CONCRETE);
        setBlock(x + 3, y + 2, z + 5, CONCRETE);
        setBlock(x + 4, y + 2, z + 5, CONCRETE);
        setBlock(x + 5, y + 2, z + 5, CONCRETE);
        setBlock(x + 6, y + 2, z + 5, CONCRETE);
        setBlock(x + 7, y + 2, z + 5, CONCRETE);
        setBlock(x + 8, y + 2, z + 5, CONCRETE);
        setBlock(x + 9, y + 2, z + 5, CONCRETE);
        setBlock(x + 10, y + 2, z + 5, CONCRETE);
        setBlock(x + 11, y + 2, z + 5, CONCRETE);
        setBlock(x, y + 2, z + 6, CONCRETE);
        setBlock(x + 1, y + 2, z + 6, CONCRETE);
        setBlock(x + 2, y + 2, z + 6, CONCRETE);
        setBlock(x + 3, y + 2, z + 6, CONCRETE);
        setBlock(x + 4, y + 2, z + 6, CONCRETE);
        setBlock(x + 5, y + 2, z + 6, CONCRETE);
        setBlock(x + 6, y + 2, z + 6, CONCRETE);
        setBlock(x + 7, y + 2, z + 6, CONCRETE);
        setBlock(x + 8, y + 2, z + 6, Blocks.VINE.defaultBlockState());
        setBlock(x + 9, y + 2, z + 6, CONCRETE);
        setBlock(x + 10, y + 2, z + 6, CONCRETE);
        setBlock(x + 11, y + 2, z + 6, CONCRETE);
        setBlock(x, y + 2, z + 7, CONCRETE);
        setBlock(x + 1, y + 2, z + 7, CONCRETE);
        setBlock(x + 2, y + 2, z + 7, CONCRETE);
        setBlock(x + 3, y + 2, z + 7, CONCRETE);
        setBlock(x + 4, y + 2, z + 7, CONCRETE);
        setBlock(x + 5, y + 2, z + 7, CONCRETE_CRACKED);
        setBlock(x + 6, y + 2, z + 7, CONCRETE_BROKEN);
        setBlock(x + 7, y + 2, z + 7, CONCRETE);
        setBlock(x + 8, y + 2, z + 7, CONCRETE);
        setBlock(x + 9, y + 2, z + 7, CONCRETE);
        setBlock(x + 10, y + 2, z + 7, CONCRETE_BROKEN);
        setBlock(x + 11, y + 2, z + 7, CONCRETE_BROKEN);
        setBlock(x, y + 2, z + 8, CONCRETE);
        setBlock(x + 1, y + 2, z + 8, CONCRETE);
        setBlock(x + 2, y + 2, z + 8, CONCRETE);
        setBlock(x + 3, y + 2, z + 8, CONCRETE_CRACKED);
        setBlock(x + 4, y + 2, z + 8, CONCRETE_BROKEN);
        setBlock(x + 5, y + 2, z + 8, CONCRETE_CRACKED);
        setBlock(x + 6, y + 2, z + 8, Blocks.NETHERRACK.defaultBlockState());
        setBlock(x + 7, y + 2, z + 8, Blocks.NETHERRACK.defaultBlockState());
        setBlock(x + 8, y + 2, z + 8, CONCRETE_BROKEN);
        setBlock(x + 9, y + 2, z + 8, CONCRETE_BROKEN);
        setBlock(x + 10, y + 2, z + 8, CONCRETE_CRACKED);
        setBlock(x + 11, y + 2, z + 8, CONCRETE);
        setBlock(x, y + 2, z + 9, CONCRETE);
        setBlock(x + 1, y + 2, z + 9, CONCRETE);
        setBlock(x + 2, y + 2, z + 9, Blocks.AIR.defaultBlockState());
        setBlock(x + 3, y + 2, z + 9, CONCRETE);
        setBlock(x + 4, y + 2, z + 9, Blocks.NETHERRACK.defaultBlockState());
        setBlock(x + 5, y + 2, z + 9, CONCRETE_CRACKED);
        setBlock(x + 6, y + 2, z + 9, CONCRETE_BROKEN);
        setBlock(x + 7, y + 2, z + 9, Blocks.NETHERRACK.defaultBlockState());
        setBlock(x + 8, y + 2, z + 9, CONCRETE_BROKEN);
        setBlock(x + 9, y + 2, z + 9, CONCRETE_BROKEN);
        setBlock(x + 10, y + 2, z + 9, CONCRETE_BROKEN);
        setBlock(x + 11, y + 2, z + 9, CONCRETE);
        setBlock(x, y + 2, z + 10, CONCRETE);
        setBlock(x + 1, y + 2, z + 10, CONCRETE);
        setBlock(x + 2, y + 2, z + 10, CONCRETE);
        setBlock(x + 3, y + 2, z + 10, Blocks.NETHERRACK.defaultBlockState());
        setBlock(x + 4, y + 2, z + 10, Blocks.NETHERRACK.defaultBlockState());
        setBlock(x + 5, y + 2, z + 10, Blocks.NETHERRACK.defaultBlockState());
        setBlock(x + 6, y + 2, z + 10, CONCRETE_CRACKED);
        setBlock(x + 7, y + 2, z + 10, CONCRETE_CRACKED);
        setBlock(x + 8, y + 2, z + 10, CONCRETE_BROKEN);
        setBlock(x + 9, y + 2, z + 10, CONCRETE_BROKEN);
        setBlock(x + 10, y + 2, z + 10, Blocks.NETHERRACK.defaultBlockState());
        setBlock(x + 11, y + 2, z + 10, CONCRETE);
        setBlock(x, y + 2, z + 11, CONCRETE);
        setBlock(x + 1, y + 2, z + 11, CONCRETE);
        setBlock(x + 2, y + 2, z + 11, CONCRETE);
        setBlock(x + 3, y + 2, z + 11, CONCRETE);
        setBlock(x + 4, y + 2, z + 11, Blocks.NETHERRACK.defaultBlockState());
        setBlock(x + 5, y + 2, z + 11, Blocks.NETHERRACK.defaultBlockState());
        setBlock(x + 6, y + 2, z + 11, CONCRETE_BROKEN);
        setBlock(x + 7, y + 2, z + 11, Blocks.NETHERRACK.defaultBlockState());
        setBlock(x + 8, y + 2, z + 11, CONCRETE_BROKEN);
        setBlock(x + 9, y + 2, z + 11, Blocks.NETHERRACK.defaultBlockState());
        setBlock(x + 10, y + 2, z + 11, Blocks.NETHERRACK.defaultBlockState());
        setBlock(x + 11, y + 2, z + 11, CONCRETE);
        setBlock(x, y + 2, z + 12, CONCRETE);
        setBlock(x + 1, y + 2, z + 12, CONCRETE);
        setBlock(x + 2, y + 2, z + 12, CONCRETE);
        setBlock(x + 3, y + 2, z + 12, CONCRETE);
        setBlock(x + 4, y + 2, z + 12, CONCRETE);
        setBlock(x + 5, y + 2, z + 12, CONCRETE);
        setBlock(x + 6, y + 2, z + 12, Blocks.NETHERRACK.defaultBlockState());
        setBlock(x + 7, y + 2, z + 12, CONCRETE);
        setBlock(x + 8, y + 2, z + 12, Blocks.NETHERRACK.defaultBlockState());
        setBlock(x + 9, y + 2, z + 12, CONCRETE);
        setBlock(x + 10, y + 2, z + 12, CONCRETE);
        setBlock(x + 11, y + 2, z + 12, CONCRETE);
        setBlock(x, y + 2, z + 13, CONCRETE);
        setBlock(x + 1, y + 2, z + 13, CONCRETE);
        setBlock(x + 2, y + 2, z + 13, CONCRETE);
        setBlock(x + 3, y + 2, z + 13, CONCRETE);
        setBlock(x + 4, y + 2, z + 13, CONCRETE);
        setBlock(x + 5, y + 2, z + 13, CONCRETE);
        setBlock(x + 6, y + 2, z + 13, CONCRETE);
        setBlock(x + 7, y + 2, z + 13, CONCRETE);
        setBlock(x + 8, y + 2, z + 13, CONCRETE);
        setBlock(x + 9, y + 2, z + 13, CONCRETE);
        setBlock(x + 10, y + 2, z + 13, CONCRETE);
        setBlock(x + 11, y + 2, z + 13, CONCRETE);
        setBlock(x + 1, y + 2, z + 14, CONCRETE);
        setBlock(x + 2, y + 2, z + 14, CONCRETE);
        setBlock(x + 3, y + 2, z + 14, CONCRETE);
        setBlock(x + 4, y + 2, z + 14, CONCRETE);
        setBlock(x + 5, y + 2, z + 14, CONCRETE);
        setBlock(x + 6, y + 2, z + 14, CONCRETE);
        setBlock(x + 7, y + 2, z + 14, CONCRETE);
        setBlock(x + 8, y + 2, z + 14, CONCRETE);
        setBlock(x + 9, y + 2, z + 14, CONCRETE);
        setBlock(x + 10, y + 2, z + 14, CONCRETE);
        setBlock(x + 11, y + 2, z + 14, CONCRETE);

        // ===== Y + 3 =====
        setBlock(x, y + 3, z + 4, CONCRETE);
        setBlock(x + 1, y + 3, z + 4, CONCRETE);
        setBlock(x + 2, y + 3, z + 4, CONCRETE);
        setBlock(x + 3, y + 3, z + 4, CONCRETE);
        setBlock(x + 4, y + 3, z + 4, CONCRETE);
        setBlock(x + 5, y + 3, z + 4, CONCRETE);
        setBlock(x + 6, y + 3, z + 4, CONCRETE);
        setBlock(x + 7, y + 3, z + 4, CONCRETE);
        setBlock(x + 8, y + 3, z + 4, CONCRETE);
        setBlock(x + 9, y + 3, z + 4, CONCRETE);
        setBlock(x + 10, y + 3, z + 4, CONCRETE);
        setBlock(x + 11, y + 3, z + 4, CONCRETE);
        setBlock(x + 12, y + 3, z + 4, CONCRETE);

        // ===== Y + 3 (продолжение) =====
        setBlock(x, y + 3, z + 5, CONCRETE);
        setBlock(x + 1, y + 3, z + 5, Blocks.SUGAR_CANE.defaultBlockState());
        setBlock(x + 2, y + 3, z + 5, Blocks.LILY_PAD.defaultBlockState());
        setBlock(x + 3, y + 3, z + 5, Blocks.LILY_PAD.defaultBlockState());
        setBlock(x + 4, y + 3, z + 5, Blocks.LILY_PAD.defaultBlockState());
        setBlock(x + 5, y + 3, z + 5, Blocks.CHEST.defaultBlockState().setValue(ChestBlock.FACING, Direction.SOUTH));
        setBlock(x + 6, y + 3, z + 5, Blocks.CHEST.defaultBlockState().setValue(ChestBlock.FACING, Direction.SOUTH));
        setBlock(x + 7, y + 3, z + 5, Blocks.AIR.defaultBlockState());
        setBlock(x + 8, y + 3, z + 5, Blocks.AIR.defaultBlockState());
        setBlock(x + 12, y + 3, z + 5, CONCRETE);

        setBlock(x, y + 3, z + 6, CONCRETE);
        setBlock(x + 1, y + 3, z + 6, ModBlocks.RED_CABLE.get().defaultBlockState());
        setBlock(x + 2, y + 3, z + 6, Blocks.AIR.defaultBlockState());
        setBlock(x + 3, y + 3, z + 6, Blocks.AIR.defaultBlockState());
        setBlock(x + 4, y + 3, z + 6, Blocks.AIR.defaultBlockState());
        setBlock(x + 5, y + 3, z + 6, Blocks.AIR.defaultBlockState());
        setBlock(x + 6, y + 3, z + 6, Blocks.AIR.defaultBlockState());
        setBlock(x + 7, y + 3, z + 6, Blocks.AIR.defaultBlockState());
        setBlock(x + 8, y + 3, z + 6, Blocks.VINE.defaultBlockState());
        setBlock(x + 9, y + 3, z + 6, Blocks.STONE.defaultBlockState());
        setBlock(x + 11, y + 3, z + 6, Blocks.STONE.defaultBlockState());
        setBlock(x + 12, y + 3, z + 6, CONCRETE);

        setBlock(x, y + 3, z + 7, CONCRETE);
        setBlock(x + 1, y + 3, z + 7, Blocks.NETHER_WART.defaultBlockState().setValue(NetherWartBlock.AGE, 3));
        setBlock(x + 2, y + 3, z + 7, Blocks.AIR.defaultBlockState());
        setBlock(x + 3, y + 3, z + 7, Blocks.AIR.defaultBlockState());
        setBlock(x + 4, y + 3, z + 7, Blocks.AIR.defaultBlockState());
        setBlock(x + 5, y + 3, z + 7, Blocks.AIR.defaultBlockState());
        setBlock(x + 6, y + 3, z + 7, Blocks.AIR.defaultBlockState());
        setBlock(x + 7, y + 3, z + 7, Blocks.AIR.defaultBlockState());
        setBlock(x + 8, y + 3, z + 7, Blocks.AIR.defaultBlockState());
        setBlock(x + 10, y + 3, z + 7, Blocks.ENDER_CHEST.defaultBlockState().setValue(ChestBlock.FACING, Direction.NORTH));
        setBlock(x + 12, y + 3, z + 7, CONCRETE);

        setBlock(x, y + 3, z + 8, CONCRETE);
        setBlock(x + 1, y + 3, z + 8, Blocks.AIR.defaultBlockState());
        setBlock(x + 2, y + 3, z + 8, Blocks.AIR.defaultBlockState());
        setBlock(x + 3, y + 3, z + 8, Blocks.AIR.defaultBlockState());
        setBlock(x + 4, y + 3, z + 8, Blocks.AIR.defaultBlockState());
        setBlock(x + 5, y + 3, z + 8, Blocks.AIR.defaultBlockState());
        setBlock(x + 6, y + 3, z + 8, Blocks.AIR.defaultBlockState());
        setBlock(x + 7, y + 3, z + 8, Blocks.AIR.defaultBlockState());
        setBlock(x + 8, y + 3, z + 8, Blocks.AIR.defaultBlockState());
        setBlock(x + 9, y + 3, z + 8, Blocks.STONE.defaultBlockState());
        setBlock(x + 11, y + 3, z + 8, Blocks.STONE.defaultBlockState());
        setBlock(x + 12, y + 3, z + 8, CONCRETE);

        setBlock(x, y + 3, z + 9, CONCRETE);
        setBlock(x + 1, y + 3, z + 9, Blocks.AIR.defaultBlockState());
        setBlock(x + 2, y + 3, z + 9, Blocks.AIR.defaultBlockState());
        setBlock(x + 3, y + 3, z + 9, Blocks.AIR.defaultBlockState());
        setBlock(x + 4, y + 3, z + 9, Blocks.AIR.defaultBlockState());
        setBlock(x + 5, y + 3, z + 9, Blocks.AIR.defaultBlockState());
        setBlock(x + 6, y + 3, z + 9, Blocks.AIR.defaultBlockState());
        setBlock(x + 7, y + 3, z + 9, Blocks.AIR.defaultBlockState());
        setBlock(x + 8, y + 3, z + 9, Blocks.AIR.defaultBlockState());
        setBlock(x + 12, y + 3, z + 9, CONCRETE);

        setBlock(x, y + 3, z + 10, CONCRETE);
        setBlock(x + 1, y + 3, z + 10, ModBlocks.MACHINE_SHREDDER.get().defaultBlockState());
        setBlock(x + 2, y + 3, z + 10, Blocks.AIR.defaultBlockState());
        setBlock(x + 3, y + 3, z + 10, Blocks.AIR.defaultBlockState());
        setBlock(x + 4, y + 3, z + 10, Blocks.AIR.defaultBlockState());
        setBlock(x + 5, y + 3, z + 10, Blocks.AIR.defaultBlockState());
        setBlock(x + 6, y + 3, z + 10, Blocks.AIR.defaultBlockState());
        setBlock(x + 7, y + 3, z + 10, Blocks.AIR.defaultBlockState());
        setBlock(x + 8, y + 3, z + 10, ModBlocks.CRASHED_BALEFIRE.get().defaultBlockState());
        setBlock(x + 9, y + 3, z + 10, Blocks.AIR.defaultBlockState());
        setBlock(x + 10, y + 3, z + 10, Blocks.AIR.defaultBlockState());
        setBlock(x + 11, y + 3, z + 10, Blocks.AIR.defaultBlockState());
        setBlock(x + 12, y + 3, z + 10, CONCRETE);

        setBlock(x, y + 3, z + 11, CONCRETE);
        setBlock(x + 1, y + 3, z + 11, Blocks.AIR.defaultBlockState());
        setBlock(x + 2, y + 3, z + 11, Blocks.AIR.defaultBlockState());
        setBlock(x + 3, y + 3, z + 11, Blocks.AIR.defaultBlockState());
        setBlock(x + 4, y + 3, z + 11, Blocks.AIR.defaultBlockState());
        setBlock(x + 5, y + 3, z + 11, Blocks.AIR.defaultBlockState());
        setBlock(x + 6, y + 3, z + 11, Blocks.AIR.defaultBlockState());
        setBlock(x + 7, y + 3, z + 11, Blocks.AIR.defaultBlockState());
        setBlock(x + 8, y + 3, z + 11, Blocks.AIR.defaultBlockState());
        setBlock(x + 9, y + 3, z + 11, Blocks.AIR.defaultBlockState());
        setBlock(x + 10, y + 3, z + 11, Blocks.AIR.defaultBlockState());
        setBlock(x + 11, y + 3, z + 11, Blocks.AIR.defaultBlockState());
        setBlock(x + 12, y + 3, z + 11, CONCRETE);

        setBlock(x, y + 3, z + 12, CONCRETE);
        setBlock(x + 1, y + 3, z + 12, Blocks.COBWEB.defaultBlockState());
        setBlock(x + 2, y + 3, z + 12, Blocks.AIR.defaultBlockState());
        setBlock(x + 3, y + 3, z + 12, Blocks.AIR.defaultBlockState());
        setBlock(x + 4, y + 3, z + 12, Blocks.AIR.defaultBlockState());
        setBlock(x + 5, y + 3, z + 12, Blocks.AIR.defaultBlockState());
        setBlock(x + 6, y + 3, z + 12, Blocks.AIR.defaultBlockState());
        setBlock(x + 7, y + 3, z + 12, Blocks.AIR.defaultBlockState());
        setBlock(x + 8, y + 3, z + 12, Blocks.AIR.defaultBlockState());
        setBlock(x + 9, y + 3, z + 12, Blocks.AIR.defaultBlockState());
        setBlock(x + 11, y + 3, z + 12, CONCRETE);
        setBlock(x + 12, y + 3, z + 12, CONCRETE);

        setBlock(x, y + 3, z + 13, CONCRETE);
        setBlock(x + 1, y + 3, z + 13, Blocks.COBWEB.defaultBlockState());
        setBlock(x + 2, y + 3, z + 13, Blocks.COBWEB.defaultBlockState());
        setBlock(x + 3, y + 3, z + 13, Blocks.AIR.defaultBlockState());
        setBlock(x + 4, y + 3, z + 13, Blocks.AIR.defaultBlockState());
        setBlock(x + 5, y + 3, z + 13, Blocks.AIR.defaultBlockState());
        setBlock(x + 6, y + 3, z + 13, Blocks.COBWEB.defaultBlockState());
        setBlock(x + 7, y + 3, z + 13, Blocks.AIR.defaultBlockState());
        setBlock(x + 8, y + 3, z + 13, Blocks.COBWEB.defaultBlockState());
        setBlock(x + 9, y + 3, z + 13, Blocks.COBWEB.defaultBlockState());
        setBlock(x + 10, y + 3, z + 13, CONCRETE);
        setBlock(x + 11, y + 3, z + 13, CONCRETE);
        setBlock(x + 12, y + 3, z + 13, CONCRETE);

        setBlock(x + 1, y + 3, z + 14, CONCRETE);
        setBlock(x + 2, y + 3, z + 14, CONCRETE);
        setBlock(x + 3, y + 3, z + 14, CONCRETE);
        setBlock(x + 4, y + 3, z + 14, CONCRETE);
        setBlock(x + 5, y + 3, z + 14, CONCRETE);
        setBlock(x + 6, y + 3, z + 14, CONCRETE);
        setBlock(x + 7, y + 3, z + 14, CONCRETE);
        setBlock(x + 8, y + 3, z + 14, CONCRETE);
        setBlock(x + 9, y + 3, z + 14, CONCRETE);
        setBlock(x + 10, y + 3, z + 14, CONCRETE);
        setBlock(x + 11, y + 3, z + 14, CONCRETE);

        // ===== Y + 4 =====
        setBlock(x, y + 4, z + 4, CONCRETE);
        setBlock(x + 1, y + 4, z + 4, CONCRETE);
        setBlock(x + 2, y + 4, z + 4, CONCRETE);
        setBlock(x + 3, y + 4, z + 4, CONCRETE);
        setBlock(x + 4, y + 4, z + 4, CONCRETE);
        setBlock(x + 5, y + 4, z + 4, CONCRETE);
        setBlock(x + 6, y + 4, z + 4, CONCRETE);
        setBlock(x + 7, y + 4, z + 4, CONCRETE);
        setBlock(x + 8, y + 4, z + 4, CONCRETE);
        setBlock(x + 9, y + 4, z + 4, CONCRETE);
        setBlock(x + 10, y + 4, z + 4, CONCRETE);
        setBlock(x + 11, y + 4, z + 4, CONCRETE);
        setBlock(x + 12, y + 4, z + 4, CONCRETE);

        setBlock(x, y + 4, z + 5, CONCRETE);
        setBlock(x + 2, y + 4, z + 5, Blocks.LILY_PAD.defaultBlockState());
        setBlock(x + 3, y + 4, z + 5, Blocks.AIR.defaultBlockState());
        setBlock(x + 4, y + 4, z + 5, Blocks.AIR.defaultBlockState());
        setBlock(x + 5, y + 4, z + 5, Blocks.CHEST.defaultBlockState().setValue(ChestBlock.FACING, Direction.SOUTH));
        setBlock(x + 6, y + 4, z + 5, Blocks.CHEST.defaultBlockState().setValue(ChestBlock.FACING, Direction.SOUTH));
        setBlock(x + 7, y + 4, z + 5, Blocks.AIR.defaultBlockState());
        setBlock(x + 8, y + 4, z + 5, Blocks.AIR.defaultBlockState());
        setBlock(x + 12, y + 4, z + 5, CONCRETE);

        setBlock(x, y + 4, z + 6, CONCRETE);
        setBlock(x + 1, y + 4, z + 6, ModBlocks.RED_CABLE.get().defaultBlockState());
        setBlock(x + 2, y + 4, z + 6, Blocks.AIR.defaultBlockState());
        setBlock(x + 3, y + 4, z + 6, Blocks.AIR.defaultBlockState());
        setBlock(x + 4, y + 4, z + 6, Blocks.AIR.defaultBlockState());
        setBlock(x + 5, y + 4, z + 6, Blocks.AIR.defaultBlockState());
        setBlock(x + 6, y + 4, z + 6, Blocks.AIR.defaultBlockState());
        setBlock(x + 7, y + 4, z + 6, Blocks.AIR.defaultBlockState());
        setBlock(x + 8, y + 4, z + 6, Blocks.AIR.defaultBlockState());
        setBlock(x + 12, y + 4, z + 6, CONCRETE);

        setBlock(x, y + 4, z + 7, CONCRETE);
        setBlock(x + 1, y + 4, z + 7, Blocks.NETHER_WART.defaultBlockState().setValue(NetherWartBlock.AGE, 3));
        setBlock(x + 2, y + 4, z + 7, Blocks.AIR.defaultBlockState());
        setBlock(x + 3, y + 4, z + 7, Blocks.AIR.defaultBlockState());
        setBlock(x + 4, y + 4, z + 7, Blocks.AIR.defaultBlockState());
        setBlock(x + 5, y + 4, z + 7, Blocks.AIR.defaultBlockState());
        setBlock(x + 6, y + 4, z + 7, Blocks.AIR.defaultBlockState());
        setBlock(x + 7, y + 4, z + 7, Blocks.AIR.defaultBlockState());
        setBlock(x + 8, y + 4, z + 7, Blocks.AIR.defaultBlockState());
        setBlock(x + 12, y + 4, z + 7, CONCRETE);

        setBlock(x, y + 4, z + 8, CONCRETE);
        setBlock(x + 1, y + 4, z + 8, Blocks.AIR.defaultBlockState());
        setBlock(x + 2, y + 4, z + 8, Blocks.AIR.defaultBlockState());
        setBlock(x + 3, y + 4, z + 8, Blocks.AIR.defaultBlockState());
        setBlock(x + 4, y + 4, z + 8, Blocks.AIR.defaultBlockState());
        setBlock(x + 5, y + 4, z + 8, Blocks.AIR.defaultBlockState());
        setBlock(x + 6, y + 4, z + 8, Blocks.AIR.defaultBlockState());
        setBlock(x + 7, y + 4, z + 8, Blocks.AIR.defaultBlockState());
        setBlock(x + 8, y + 4, z + 8, Blocks.AIR.defaultBlockState());
        setBlock(x + 12, y + 4, z + 8, CONCRETE);

        setBlock(x, y + 4, z + 9, CONCRETE);
        setBlock(x + 1, y + 4, z + 9, Blocks.AIR.defaultBlockState());
        setBlock(x + 2, y + 4, z + 9, Blocks.AIR.defaultBlockState());
        setBlock(x + 3, y + 4, z + 9, Blocks.AIR.defaultBlockState());
        setBlock(x + 4, y + 4, z + 9, Blocks.AIR.defaultBlockState());
        setBlock(x + 5, y + 4, z + 9, Blocks.AIR.defaultBlockState());
        setBlock(x + 6, y + 4, z + 9, Blocks.AIR.defaultBlockState());
        setBlock(x + 7, y + 4, z + 9, Blocks.AIR.defaultBlockState());
        setBlock(x + 8, y + 4, z + 9, Blocks.AIR.defaultBlockState());
        setBlock(x + 12, y + 4, z + 9, CONCRETE);

        setBlock(x, y + 4, z + 10, CONCRETE);
        setBlock(x + 1, y + 4, z + 10, ModBlocks.RED_CABLE.get().defaultBlockState());
        setBlock(x + 2, y + 4, z + 10, Blocks.AIR.defaultBlockState());
        setBlock(x + 3, y + 4, z + 10, Blocks.AIR.defaultBlockState());
        setBlock(x + 4, y + 4, z + 10, Blocks.AIR.defaultBlockState());
        setBlock(x + 5, y + 4, z + 10, Blocks.AIR.defaultBlockState());
        setBlock(x + 6, y + 4, z + 10, Blocks.AIR.defaultBlockState());
        setBlock(x + 7, y + 4, z + 10, Blocks.AIR.defaultBlockState());
        setBlock(x + 8, y + 4, z + 10, Blocks.AIR.defaultBlockState());
        setBlock(x + 9, y + 4, z + 10, Blocks.AIR.defaultBlockState());
        setBlock(x + 10, y + 4, z + 10, Blocks.AIR.defaultBlockState());
        setBlock(x + 11, y + 4, z + 10, Blocks.AIR.defaultBlockState());
        setBlock(x + 12, y + 4, z + 10, CONCRETE);

        setBlock(x, y + 4, z + 11, CONCRETE);
        setBlock(x + 1, y + 4, z + 11, Blocks.AIR.defaultBlockState());
        setBlock(x + 2, y + 4, z + 11, Blocks.AIR.defaultBlockState());
        setBlock(x + 3, y + 4, z + 11, Blocks.AIR.defaultBlockState());
        setBlock(x + 4, y + 4, z + 11, Blocks.AIR.defaultBlockState());
        setBlock(x + 5, y + 4, z + 11, Blocks.AIR.defaultBlockState());
        setBlock(x + 6, y + 4, z + 11, Blocks.AIR.defaultBlockState());
        setBlock(x + 7, y + 4, z + 11, Blocks.AIR.defaultBlockState());
        setBlock(x + 8, y + 4, z + 11, Blocks.AIR.defaultBlockState());
        setBlock(x + 9, y + 4, z + 11, Blocks.AIR.defaultBlockState());
        setBlock(x + 10, y + 4, z + 11, Blocks.AIR.defaultBlockState());
        setBlock(x + 11, y + 4, z + 11, Blocks.AIR.defaultBlockState());
        setBlock(x + 12, y + 4, z + 11, CONCRETE);

        setBlock(x, y + 4, z + 12, CONCRETE);
        setBlock(x + 1, y + 4, z + 12, Blocks.AIR.defaultBlockState());
        setBlock(x + 2, y + 4, z + 12, Blocks.AIR.defaultBlockState());
        setBlock(x + 3, y + 4, z + 12, Blocks.AIR.defaultBlockState());
        setBlock(x + 4, y + 4, z + 12, Blocks.AIR.defaultBlockState());
        setBlock(x + 5, y + 4, z + 12, Blocks.AIR.defaultBlockState());
        setBlock(x + 6, y + 4, z + 12, Blocks.AIR.defaultBlockState());
        setBlock(x + 7, y + 4, z + 12, Blocks.AIR.defaultBlockState());
        setBlock(x + 8, y + 4, z + 12, Blocks.AIR.defaultBlockState());
        setBlock(x + 9, y + 4, z + 12, Blocks.AIR.defaultBlockState());
        setBlock(x + 11, y + 4, z + 12, CONCRETE);
        setBlock(x + 12, y + 4, z + 12, CONCRETE);

        setBlock(x, y + 4, z + 13, CONCRETE);
        setBlock(x + 1, y + 4, z + 13, Blocks.AIR.defaultBlockState());
        setBlock(x + 2, y + 4, z + 13, Blocks.COBWEB.defaultBlockState());
        setBlock(x + 3, y + 4, z + 13, Blocks.AIR.defaultBlockState());
        setBlock(x + 4, y + 4, z + 13, Blocks.AIR.defaultBlockState());
        setBlock(x + 5, y + 4, z + 13, Blocks.AIR.defaultBlockState());
        setBlock(x + 7, y + 4, z + 13, Blocks.AIR.defaultBlockState());
        setBlock(x + 8, y + 4, z + 13, Blocks.AIR.defaultBlockState());
        setBlock(x + 9, y + 4, z + 13, Blocks.COBWEB.defaultBlockState());
        setBlock(x + 10, y + 4, z + 13, CONCRETE);
        setBlock(x + 11, y + 4, z + 13, CONCRETE);
        setBlock(x + 12, y + 4, z + 13, CONCRETE);

        setBlock(x + 1, y + 4, z + 14, CONCRETE);
        setBlock(x + 2, y + 4, z + 14, CONCRETE);
        setBlock(x + 3, y + 4, z + 14, CONCRETE);
        setBlock(x + 4, y + 4, z + 14, CONCRETE);
        setBlock(x + 5, y + 4, z + 14, CONCRETE);
        setBlock(x + 6, y + 4, z + 14, CONCRETE);
        setBlock(x + 7, y + 4, z + 14, CONCRETE);
        setBlock(x + 8, y + 4, z + 14, CONCRETE);
        setBlock(x + 9, y + 4, z + 14, CONCRETE);
        setBlock(x + 10, y + 4, z + 14, CONCRETE);
        setBlock(x + 11, y + 4, z + 14, CONCRETE);

    }

    public void generate_r1()
    {
        int x = originX;
        int y = originY;
        int z = originZ;

        setBlock(x, y + 5, z + 4, CONCRETE);
        setBlock(x + 1, y + 5, z + 4, CONCRETE);
        setBlock(x + 2, y + 5, z + 4, CONCRETE);
        setBlock(x + 3, y + 5, z + 4, CONCRETE);
        setBlock(x + 4, y + 5, z + 4, CONCRETE);
        setBlock(x + 5, y + 5, z + 4, CONCRETE);
        setBlock(x + 6, y + 5, z + 4, CONCRETE);
        setBlock(x + 7, y + 5, z + 4, CONCRETE);
        setBlock(x + 8, y + 5, z + 4, CONCRETE);
        setBlock(x + 9, y + 5, z + 4, CONCRETE);
        setBlock(x + 10, y + 5, z + 4, CONCRETE);
        setBlock(x + 11, y + 5, z + 4, CONCRETE);
        setBlock(x + 12, y + 5, z + 4, CONCRETE);

        setBlock(x, y + 5, z + 5, CONCRETE);
        setBlock(x + 1, y + 5, z + 5, Blocks.AIR.defaultBlockState());
        setBlock(x + 2, y + 5, z + 5, Blocks.AIR.defaultBlockState());
        setBlock(x + 3, y + 5, z + 5, Blocks.AIR.defaultBlockState());
        setBlock(x + 4, y + 5, z + 5, Blocks.AIR.defaultBlockState());
        setBlock(x + 5, y + 5, z + 5, Blocks.CHEST.defaultBlockState().setValue(ChestBlock.FACING, Direction.SOUTH));
        setBlock(x + 6, y + 5, z + 5, Blocks.CHEST.defaultBlockState().setValue(ChestBlock.FACING, Direction.SOUTH));
        setBlock(x + 7, y + 5, z + 5, Blocks.AIR.defaultBlockState());
        setBlock(x + 8, y + 5, z + 5, Blocks.AIR.defaultBlockState());
        setBlock(x + 12, y + 5, z + 5, CONCRETE);

        setBlock(x, y + 5, z + 6, CONCRETE);
        setBlock(x + 1, y + 5, z + 6, RED_CABLE);
        setBlock(x + 2, y + 5, z + 6, Blocks.AIR.defaultBlockState());
        setBlock(x + 3, y + 5, z + 6, Blocks.AIR.defaultBlockState());
        setBlock(x + 4, y + 5, z + 6, Blocks.AIR.defaultBlockState());
        setBlock(x + 5, y + 5, z + 6, Blocks.AIR.defaultBlockState());
        setBlock(x + 6, y + 5, z + 6, Blocks.AIR.defaultBlockState());
        setBlock(x + 7, y + 5, z + 6, Blocks.AIR.defaultBlockState());
        setBlock(x + 8, y + 5, z + 6, Blocks.AIR.defaultBlockState());
        setBlock(x + 12, y + 5, z + 6, CONCRETE);

        setBlock(x, y + 5, z + 7, CONCRETE);
        setBlock(x + 1, y + 5, z + 7, Blocks.AIR.defaultBlockState());
        setBlock(x + 2, y + 5, z + 7, Blocks.AIR.defaultBlockState());
        setBlock(x + 3, y + 5, z + 7, Blocks.AIR.defaultBlockState());
        setBlock(x + 4, y + 5, z + 7, Blocks.AIR.defaultBlockState());
        setBlock(x + 5, y + 5, z + 7, Blocks.AIR.defaultBlockState());
        setBlock(x + 6, y + 5, z + 7, Blocks.AIR.defaultBlockState());
        setBlock(x + 7, y + 5, z + 7, Blocks.AIR.defaultBlockState());
        setBlock(x + 8, y + 5, z + 7, Blocks.AIR.defaultBlockState());
        setBlock(x + 12, y + 5, z + 7, CONCRETE);

        setBlock(x, y + 5, z + 8, CONCRETE);
        setBlock(x + 1, y + 5, z + 8, Blocks.AIR.defaultBlockState());
        setBlock(x + 2, y + 5, z + 8, Blocks.AIR.defaultBlockState());
        setBlock(x + 3, y + 5, z + 8, Blocks.AIR.defaultBlockState());
        setBlock(x + 4, y + 5, z + 8, Blocks.AIR.defaultBlockState());
        setBlock(x + 5, y + 5, z + 8, Blocks.AIR.defaultBlockState());
        setBlock(x + 6, y + 5, z + 8, Blocks.AIR.defaultBlockState());
        setBlock(x + 7, y + 5, z + 8, Blocks.AIR.defaultBlockState());
        setBlock(x + 8, y + 5, z + 8, Blocks.AIR.defaultBlockState());
        setBlock(x + 12, y + 5, z + 8, CONCRETE);

        setBlock(x, y + 5, z + 9, CONCRETE);
        setBlock(x + 1, y + 5, z + 9, Blocks.AIR.defaultBlockState());
        setBlock(x + 2, y + 5, z + 9, Blocks.AIR.defaultBlockState());
        setBlock(x + 3, y + 5, z + 9, Blocks.AIR.defaultBlockState());
        setBlock(x + 4, y + 5, z + 9, Blocks.AIR.defaultBlockState());
        setBlock(x + 5, y + 5, z + 9, Blocks.AIR.defaultBlockState());
        setBlock(x + 6, y + 5, z + 9, Blocks.AIR.defaultBlockState());
        setBlock(x + 7, y + 5, z + 9, Blocks.AIR.defaultBlockState());
        setBlock(x + 8, y + 5, z + 9, Blocks.AIR.defaultBlockState());
        setBlock(x + 12, y + 5, z + 9, CONCRETE);

        setBlock(x, y + 5, z + 10, CONCRETE);
        setBlock(x + 1, y + 5, z + 10, RED_CABLE);
        setBlock(x + 2, y + 5, z + 10, Blocks.AIR.defaultBlockState());
        setBlock(x + 3, y + 5, z + 10, Blocks.AIR.defaultBlockState());
        setBlock(x + 4, y + 5, z + 10, Blocks.AIR.defaultBlockState());
        setBlock(x + 5, y + 5, z + 10, Blocks.AIR.defaultBlockState());
        setBlock(x + 6, y + 5, z + 10, Blocks.AIR.defaultBlockState());
        setBlock(x + 7, y + 5, z + 10, Blocks.AIR.defaultBlockState());
        setBlock(x + 8, y + 5, z + 10, Blocks.AIR.defaultBlockState());
        setBlock(x + 9, y + 5, z + 10, Blocks.AIR.defaultBlockState());
        setBlock(x + 10, y + 5, z + 10, Blocks.AIR.defaultBlockState());
        setBlock(x + 11, y + 5, z + 10, Blocks.AIR.defaultBlockState());
        setBlock(x + 12, y + 5, z + 10, CONCRETE);

        setBlock(x, y + 5, z + 11, CONCRETE);
        setBlock(x + 1, y + 5, z + 11, Blocks.AIR.defaultBlockState());
        setBlock(x + 2, y + 5, z + 11, Blocks.AIR.defaultBlockState());
        setBlock(x + 3, y + 5, z + 11, Blocks.AIR.defaultBlockState());
        setBlock(x + 4, y + 5, z + 11, Blocks.AIR.defaultBlockState());
        setBlock(x + 5, y + 5, z + 11, Blocks.AIR.defaultBlockState());
        setBlock(x + 6, y + 5, z + 11, Blocks.AIR.defaultBlockState());
        setBlock(x + 7, y + 5, z + 11, Blocks.AIR.defaultBlockState());
        setBlock(x + 8, y + 5, z + 11, Blocks.AIR.defaultBlockState());
        setBlock(x + 9, y + 5, z + 11, Blocks.AIR.defaultBlockState());
        setBlock(x + 10, y + 5, z + 11, Blocks.AIR.defaultBlockState());
        setBlock(x + 11, y + 5, z + 11, Blocks.AIR.defaultBlockState());
        setBlock(x + 12, y + 5, z + 11, CONCRETE);

        setBlock(x, y + 5, z + 12, CONCRETE);
        setBlock(x + 1, y + 5, z + 12, Blocks.AIR.defaultBlockState());
        setBlock(x + 2, y + 5, z + 12, Blocks.AIR.defaultBlockState());
        setBlock(x + 3, y + 5, z + 12, Blocks.AIR.defaultBlockState());
        setBlock(x + 4, y + 5, z + 12, Blocks.AIR.defaultBlockState());
        setBlock(x + 5, y + 5, z + 12, Blocks.AIR.defaultBlockState());
        setBlock(x + 6, y + 5, z + 12, Blocks.AIR.defaultBlockState());
        setBlock(x + 7, y + 5, z + 12, Blocks.AIR.defaultBlockState());
        setBlock(x + 8, y + 5, z + 12, Blocks.AIR.defaultBlockState());
        setBlock(x + 9, y + 5, z + 12, Blocks.AIR.defaultBlockState());
        setBlock(x + 11, y + 5, z + 12, CONCRETE);
        setBlock(x + 12, y + 5, z + 12, CONCRETE);

        setBlock(x, y + 5, z + 13, CONCRETE);
        setBlock(x + 1, y + 5, z + 13, Blocks.COBWEB.defaultBlockState());
        setBlock(x + 2, y + 5, z + 13, Blocks.AIR.defaultBlockState());
        setBlock(x + 3, y + 5, z + 13, Blocks.AIR.defaultBlockState());
        setBlock(x + 4, y + 5, z + 13, Blocks.AIR.defaultBlockState());
        setBlock(x + 5, y + 5, z + 13, Blocks.AIR.defaultBlockState());
        setBlock(x + 6, y + 5, z + 13, Blocks.AIR.defaultBlockState());
        setBlock(x + 7, y + 5, z + 13, Blocks.AIR.defaultBlockState());
        setBlock(x + 8, y + 5, z + 13, Blocks.AIR.defaultBlockState());
        setBlock(x + 9, y + 5, z + 13, Blocks.AIR.defaultBlockState());
        setBlock(x + 10, y + 5, z + 13, CONCRETE);
        setBlock(x + 11, y + 5, z + 13, CONCRETE);
        setBlock(x + 12, y + 5, z + 13, CONCRETE);

        setBlock(x + 1, y + 5, z + 14, CONCRETE);
        setBlock(x + 2, y + 5, z + 14, CONCRETE);
        setBlock(x + 3, y + 5, z + 14, CONCRETE);
        setBlock(x + 4, y + 5, z + 14, CONCRETE);
        setBlock(x + 5, y + 5, z + 14, CONCRETE);
        setBlock(x + 6, y + 5, z + 14, CONCRETE);
        setBlock(x + 7, y + 5, z + 14, CONCRETE);
        setBlock(x + 8, y + 5, z + 14, CONCRETE);
        setBlock(x + 9, y + 5, z + 14, CONCRETE);
        setBlock(x + 10, y + 5, z + 14, CONCRETE);
        setBlock(x + 11, y + 5, z + 14, CONCRETE);

        // Y+6
        setBlock(x, y + 6, z + 4, CONCRETE);
        setBlock(x + 1, y + 6, z + 4, CONCRETE);
        setBlock(x + 2, y + 6, z + 4, CONCRETE);
        setBlock(x + 3, y + 6, z + 4, CONCRETE);
        setBlock(x + 4, y + 6, z + 4, CONCRETE);
        setBlock(x + 5, y + 6, z + 4, CONCRETE);
        setBlock(x + 6, y + 6, z + 4, CONCRETE);
        setBlock(x + 7, y + 6, z + 4, CONCRETE);
        setBlock(x + 8, y + 6, z + 4, CONCRETE);
        setBlock(x + 9, y + 6, z + 4, CONCRETE);
        setBlock(x + 10, y + 6, z + 4, CONCRETE);
        setBlock(x + 11, y + 6, z + 4, CONCRETE);
        setBlock(x + 12, y + 6, z + 4, CONCRETE);

        setBlock(x, y + 6, z + 5, CONCRETE);
        setBlock(x + 1, y + 6, z + 5, Blocks.AIR.defaultBlockState());
        setBlock(x + 2, y + 6, z + 5, Blocks.AIR.defaultBlockState());
        setBlock(x + 3, y + 6, z + 5, Blocks.AIR.defaultBlockState());
        setBlock(x + 4, y + 6, z + 5, Blocks.AIR.defaultBlockState());
        setBlock(x + 5, y + 6, z + 5, Blocks.AIR.defaultBlockState());
        setBlock(x + 6, y + 6, z + 5, Blocks.AIR.defaultBlockState());
        setBlock(x + 7, y + 6, z + 5, Blocks.AIR.defaultBlockState());
        setBlock(x + 8, y + 6, z + 5, Blocks.AIR.defaultBlockState());
        setBlock(x + 9, y + 6, z + 5, Blocks.AIR.defaultBlockState());
        setBlock(x + 10, y + 6, z + 5, Blocks.COBWEB.defaultBlockState());
        setBlock(x + 11, y + 6, z + 5, Blocks.COBWEB.defaultBlockState());
        setBlock(x + 12, y + 6, z + 5, CONCRETE);

        setBlock(x, y + 6, z + 6, CONCRETE);
        setBlock(x + 1, y + 6, z + 6, RED_CABLE);
        setBlock(x + 2, y + 6, z + 6, Blocks.AIR.defaultBlockState());
        setBlock(x + 3, y + 6, z + 6, Blocks.AIR.defaultBlockState());
        setBlock(x + 4, y + 6, z + 6, Blocks.AIR.defaultBlockState());
        setBlock(x + 5, y + 6, z + 6, Blocks.AIR.defaultBlockState());
        setBlock(x + 6, y + 6, z + 6, Blocks.AIR.defaultBlockState());
        setBlock(x + 7, y + 6, z + 6, Blocks.AIR.defaultBlockState());
        setBlock(x + 8, y + 6, z + 6, Blocks.AIR.defaultBlockState());
        setBlock(x + 9, y + 6, z + 6, Blocks.AIR.defaultBlockState());
        setBlock(x + 10, y + 6, z + 6, Blocks.AIR.defaultBlockState());
        setBlock(x + 11, y + 6, z + 6, Blocks.COBWEB.defaultBlockState());
        setBlock(x + 12, y + 6, z + 6, CONCRETE);

        setBlock(x, y + 6, z + 7, CONCRETE);
        setBlock(x + 1, y + 6, z + 7, RED_CABLE);
        setBlock(x + 2, y + 6, z + 7, Blocks.AIR.defaultBlockState());
        setBlock(x + 3, y + 6, z + 7, Blocks.AIR.defaultBlockState());
        setBlock(x + 4, y + 6, z + 7, Blocks.AIR.defaultBlockState());
        setBlock(x + 5, y + 6, z + 7, Blocks.AIR.defaultBlockState());
        setBlock(x + 6, y + 6, z + 7, Blocks.AIR.defaultBlockState());
        setBlock(x + 7, y + 6, z + 7, Blocks.AIR.defaultBlockState());
        setBlock(x + 8, y + 6, z + 7, Blocks.AIR.defaultBlockState());
        setBlock(x + 9, y + 6, z + 7, Blocks.AIR.defaultBlockState());
        setBlock(x + 10, y + 6, z + 7, Blocks.AIR.defaultBlockState());
        setBlock(x + 11, y + 6, z + 7, Blocks.AIR.defaultBlockState());
        setBlock(x + 12, y + 6, z + 7, CONCRETE);

        setBlock(x, y + 6, z + 8, CONCRETE);
        setBlock(x + 1, y + 6, z + 8, RED_CABLE);
        setBlock(x + 2, y + 6, z + 8, Blocks.AIR.defaultBlockState());
        setBlock(x + 3, y + 6, z + 8, Blocks.AIR.defaultBlockState());
        setBlock(x + 4, y + 6, z + 8, Blocks.AIR.defaultBlockState());
        setBlock(x + 5, y + 6, z + 8, Blocks.AIR.defaultBlockState());
        setBlock(x + 6, y + 6, z + 8, Blocks.AIR.defaultBlockState());
        setBlock(x + 7, y + 6, z + 8, Blocks.AIR.defaultBlockState());
        setBlock(x + 8, y + 6, z + 8, Blocks.AIR.defaultBlockState());
        setBlock(x + 9, y + 6, z + 8, Blocks.AIR.defaultBlockState());
        setBlock(x + 10, y + 6, z + 8, Blocks.AIR.defaultBlockState());
        setBlock(x + 11, y + 6, z + 8, Blocks.COBWEB.defaultBlockState());
        setBlock(x + 12, y + 6, z + 8, CONCRETE);

        setBlock(x, y + 6, z + 9, CONCRETE);
        setBlock(x + 1, y + 6, z + 9, CABLE_SWITCH);
        setBlock(x + 2, y + 6, z + 9, Blocks.AIR.defaultBlockState());
        setBlock(x + 3, y + 6, z + 9, Blocks.AIR.defaultBlockState());
        setBlock(x + 4, y + 6, z + 9, Blocks.AIR.defaultBlockState());
        setBlock(x + 5, y + 6, z + 9, Blocks.AIR.defaultBlockState());
        setBlock(x + 6, y + 6, z + 9, Blocks.AIR.defaultBlockState());
        setBlock(x + 7, y + 6, z + 9, Blocks.AIR.defaultBlockState());
        setBlock(x + 8, y + 6, z + 9, Blocks.AIR.defaultBlockState());
        setBlock(x + 9, y + 6, z + 9, Blocks.AIR.defaultBlockState());
        setBlock(x + 10, y + 6, z + 9, Blocks.AIR.defaultBlockState());
        setBlock(x + 11, y + 6, z + 9, Blocks.AIR.defaultBlockState());
        setBlock(x + 12, y + 6, z + 9, CONCRETE);

        setBlock(x, y + 6, z + 10, CONCRETE);
        setBlock(x + 1, y + 6, z + 10, RED_CABLE);
        setBlock(x + 2, y + 6, z + 10, RED_CABLE);
        setBlock(x + 3, y + 6, z + 10, Blocks.AIR.defaultBlockState());
        setBlock(x + 4, y + 6, z + 10, Blocks.AIR.defaultBlockState());
        setBlock(x + 5, y + 6, z + 10, Blocks.AIR.defaultBlockState());
        setBlock(x + 6, y + 6, z + 10, Blocks.AIR.defaultBlockState());
        setBlock(x + 7, y + 6, z + 10, Blocks.AIR.defaultBlockState());
        setBlock(x + 8, y + 6, z + 10, Blocks.AIR.defaultBlockState());
        setBlock(x + 9, y + 6, z + 10, Blocks.AIR.defaultBlockState());
        setBlock(x + 10, y + 6, z + 10, Blocks.AIR.defaultBlockState());
        setBlock(x + 11, y + 6, z + 10, Blocks.COBWEB.defaultBlockState());
        setBlock(x + 12, y + 6, z + 10, CONCRETE);

        setBlock(x, y + 6, z + 11, CONCRETE);
        setBlock(x + 1, y + 6, z + 11, RED_CABLE);
        setBlock(x + 2, y + 6, z + 11, Blocks.AIR.defaultBlockState());
        setBlock(x + 3, y + 6, z + 11, Blocks.AIR.defaultBlockState());
        setBlock(x + 4, y + 6, z + 11, Blocks.AIR.defaultBlockState());
        setBlock(x + 5, y + 6, z + 11, Blocks.AIR.defaultBlockState());
        setBlock(x + 6, y + 6, z + 11, Blocks.AIR.defaultBlockState());
        setBlock(x + 7, y + 6, z + 11, Blocks.AIR.defaultBlockState());
        setBlock(x + 8, y + 6, z + 11, Blocks.AIR.defaultBlockState());
        setBlock(x + 9, y + 6, z + 11, Blocks.AIR.defaultBlockState());
        setBlock(x + 10, y + 6, z + 11, Blocks.AIR.defaultBlockState());
        setBlock(x + 11, y + 6, z + 11, Blocks.AIR.defaultBlockState());
        setBlock(x + 12, y + 6, z + 11, CONCRETE);

        setBlock(x, y + 6, z + 12, CONCRETE);
        setBlock(x + 1, y + 6, z + 12, RED_CABLE);
        setBlock(x + 2, y + 6, z + 12, RED_CABLE);
        setBlock(x + 3, y + 6, z + 12, Blocks.AIR.defaultBlockState());
        setBlock(x + 4, y + 6, z + 12, Blocks.AIR.defaultBlockState());
        setBlock(x + 5, y + 6, z + 12, Blocks.AIR.defaultBlockState());
        setBlock(x + 6, y + 6, z + 12, Blocks.AIR.defaultBlockState());
        setBlock(x + 7, y + 6, z + 12, Blocks.AIR.defaultBlockState());
        setBlock(x + 8, y + 6, z + 12, Blocks.AIR.defaultBlockState());
        setBlock(x + 9, y + 6, z + 12, Blocks.AIR.defaultBlockState());
        setBlock(x + 11, y + 6, z + 12, CONCRETE);
        setBlock(x + 12, y + 6, z + 12, CONCRETE);

        setBlock(x, y + 6, z + 13, CONCRETE);
        setBlock(x + 1, y + 6, z + 13, Blocks.COBWEB.defaultBlockState());
        setBlock(x + 2, y + 6, z + 13, Blocks.COBWEB.defaultBlockState());
        setBlock(x + 3, y + 6, z + 13, Blocks.AIR.defaultBlockState());
        setBlock(x + 4, y + 6, z + 13, Blocks.AIR.defaultBlockState());
        setBlock(x + 5, y + 6, z + 13, Blocks.AIR.defaultBlockState());
        setBlock(x + 6, y + 6, z + 13, Blocks.AIR.defaultBlockState());
        setBlock(x + 7, y + 6, z + 13, Blocks.AIR.defaultBlockState());
        setBlock(x + 8, y + 6, z + 13, Blocks.AIR.defaultBlockState());
        setBlock(x + 9, y + 6, z + 13, Blocks.AIR.defaultBlockState());
        setBlock(x + 10, y + 6, z + 13, CONCRETE);
        setBlock(x + 11, y + 6, z + 13, CONCRETE);
        setBlock(x + 12, y + 6, z + 13, CONCRETE);

        setBlock(x + 1, y + 6, z + 14, CONCRETE);
        setBlock(x + 2, y + 6, z + 14, CONCRETE);
        setBlock(x + 3, y + 6, z + 14, CONCRETE);
        setBlock(x + 4, y + 6, z + 14, CONCRETE);
        setBlock(x + 5, y + 6, z + 14, CONCRETE);
        setBlock(x + 6, y + 6, z + 14, CONCRETE);
        setBlock(x + 7, y + 6, z + 14, CONCRETE);
        setBlock(x + 8, y + 6, z + 14, CONCRETE);
        setBlock(x + 9, y + 6, z + 14, CONCRETE);
        setBlock(x + 10, y + 6, z + 14, CONCRETE);
        setBlock(x + 11, y + 6, z + 14, CONCRETE);

        // Y+7
        setBlock(x, y + 7, z + 4, CONCRETE);
        setBlock(x + 1, y + 7, z + 4, CONCRETE);
        setBlock(x + 2, y + 7, z + 4, CONCRETE);
        setBlock(x + 3, y + 7, z + 4, CONCRETE);
        setBlock(x + 4, y + 7, z + 4, CONCRETE);
        setBlock(x + 5, y + 7, z + 4, CONCRETE);
        setBlock(x + 6, y + 7, z + 4, CONCRETE);
        setBlock(x + 7, y + 7, z + 4, CONCRETE);
        setBlock(x + 8, y + 7, z + 4, CONCRETE);
        setBlock(x + 9, y + 7, z + 4, CONCRETE);
        setBlock(x + 10, y + 7, z + 4, CONCRETE);
        setBlock(x + 11, y + 7, z + 4, CONCRETE);

        setBlock(x, y + 7, z + 5, CONCRETE);
        setBlock(x + 1, y + 7, z + 5, CONCRETE);
        setBlock(x + 2, y + 7, z + 5, CONCRETE);
        setBlock(x + 3, y + 7, z + 5, CONCRETE);
        setBlock(x + 4, y + 7, z + 5, CONCRETE);
        setBlock(x + 5, y + 7, z + 5, CONCRETE);
        setBlock(x + 6, y + 7, z + 5, CONCRETE);
        setBlock(x + 7, y + 7, z + 5, CONCRETE);
        setBlock(x + 8, y + 7, z + 5, CONCRETE);
        setBlock(x + 9, y + 7, z + 5, CONCRETE);
        setBlock(x + 10, y + 7, z + 5, CONCRETE);
        setBlock(x + 11, y + 7, z + 5, CONCRETE);

        setBlock(x, y + 7, z + 6, CONCRETE);
        setBlock(x + 1, y + 7, z + 6, CONCRETE);
        setBlock(x + 2, y + 7, z + 6, CONCRETE);
        setBlock(x + 3, y + 7, z + 6, CONCRETE);
        setBlock(x + 4, y + 7, z + 6, CONCRETE);
        setBlock(x + 5, y + 7, z + 6, CONCRETE);
        setBlock(x + 6, y + 7, z + 6, CONCRETE);
        setBlock(x + 7, y + 7, z + 6, CONCRETE);
        setBlock(x + 8, y + 7, z + 6, CONCRETE);
        setBlock(x + 9, y + 7, z + 6, CONCRETE);
        setBlock(x + 10, y + 7, z + 6, CONCRETE);
        setBlock(x + 11, y + 7, z + 6, CONCRETE);

        setBlock(x, y + 7, z + 7, CONCRETE);
        setBlock(x + 1, y + 7, z + 7, CONCRETE);
        setBlock(x + 2, y + 7, z + 7, CONCRETE);
        setBlock(x + 3, y + 7, z + 7, CONCRETE);
        setBlock(x + 4, y + 7, z + 7, CONCRETE);
        setBlock(x + 5, y + 7, z + 7, CONCRETE);
        setBlock(x + 6, y + 7, z + 7, CONCRETE);
        setBlock(x + 7, y + 7, z + 7, CONCRETE);
        setBlock(x + 8, y + 7, z + 7, Blocks.AIR.defaultBlockState());
        setBlock(x + 9, y + 7, z + 7, CONCRETE);
        setBlock(x + 10, y + 7, z + 7, CONCRETE);
        setBlock(x + 11, y + 7, z + 7, CONCRETE);

        setBlock(x, y + 7, z + 8, CONCRETE);
        setBlock(x + 1, y + 7, z + 8, CONCRETE);
        setBlock(x + 2, y + 7, z + 8, CONCRETE);
        setBlock(x + 3, y + 7, z + 8, CONCRETE);
        setBlock(x + 4, y + 7, z + 8, CONCRETE);
        setBlock(x + 5, y + 7, z + 8, CONCRETE);
        setBlock(x + 6, y + 7, z + 8, CONCRETE);
        setBlock(x + 7, y + 7, z + 8, Blocks.AIR.defaultBlockState());
        setBlock(x + 8, y + 7, z + 8, Blocks.AIR.defaultBlockState());
        setBlock(x + 9, y + 7, z + 8, CONCRETE);
        setBlock(x + 10, y + 7, z + 8, CONCRETE);
        setBlock(x + 11, y + 7, z + 8, CONCRETE);

        setBlock(x, y + 7, z + 9, CONCRETE);
        setBlock(x + 1, y + 7, z + 9, CONCRETE);
        setBlock(x + 2, y + 7, z + 9, CONCRETE);
        setBlock(x + 3, y + 7, z + 9, CONCRETE);
        setBlock(x + 4, y + 7, z + 9, CONCRETE);
        setBlock(x + 5, y + 7, z + 9, CONCRETE);
        setBlock(x + 6, y + 7, z + 9, Blocks.AIR.defaultBlockState());
        setBlock(x + 7, y + 7, z + 9, Blocks.AIR.defaultBlockState());
        setBlock(x + 8, y + 7, z + 9, Blocks.AIR.defaultBlockState());
        setBlock(x + 9, y + 7, z + 9, Blocks.AIR.defaultBlockState());
        setBlock(x + 10, y + 7, z + 9, CONCRETE);
        setBlock(x + 11, y + 7, z + 9, CONCRETE);

        setBlock(x, y + 7, z + 10, CONCRETE);
        setBlock(x + 1, y + 7, z + 10, CONCRETE);
        setBlock(x + 2, y + 7, z + 10, RED_CABLE);
        setBlock(x + 3, y + 7, z + 10, CONCRETE);
        setBlock(x + 4, y + 7, z + 10, CONCRETE);
        setBlock(x + 5, y + 7, z + 10, Blocks.AIR.defaultBlockState());
        setBlock(x + 6, y + 7, z + 10, Blocks.AIR.defaultBlockState());
        setBlock(x + 7, y + 7, z + 10, Blocks.AIR.defaultBlockState());
        setBlock(x + 8, y + 7, z + 10, Blocks.AIR.defaultBlockState());
        setBlock(x + 9, y + 7, z + 10, Blocks.AIR.defaultBlockState());
        setBlock(x + 10, y + 7, z + 10, CONCRETE);
        setBlock(x + 11, y + 7, z + 10, CONCRETE);

        setBlock(x, y + 7, z + 11, CONCRETE);
        setBlock(x + 1, y + 7, z + 11, CONCRETE);
        setBlock(x + 2, y + 7, z + 11, CONCRETE);
        setBlock(x + 3, y + 7, z + 11, CONCRETE);
        setBlock(x + 4, y + 7, z + 11, Blocks.AIR.defaultBlockState());
        setBlock(x + 5, y + 7, z + 11, Blocks.AIR.defaultBlockState());
        setBlock(x + 6, y + 7, z + 11, Blocks.AIR.defaultBlockState());
        setBlock(x + 7, y + 7, z + 11, Blocks.AIR.defaultBlockState());
        setBlock(x + 8, y + 7, z + 11, Blocks.AIR.defaultBlockState());
        setBlock(x + 9, y + 7, z + 11, CONCRETE);
        setBlock(x + 10, y + 7, z + 11, CONCRETE);
        setBlock(x + 11, y + 7, z + 11, CONCRETE);

        setBlock(x, y + 7, z + 12, CONCRETE);
        setBlock(x + 1, y + 7, z + 12, CONCRETE);
        setBlock(x + 2, y + 7, z + 12, RED_CABLE);
        setBlock(x + 3, y + 7, z + 12, CONCRETE);
        setBlock(x + 4, y + 7, z + 12, CONCRETE);
        setBlock(x + 5, y + 7, z + 12, Blocks.AIR.defaultBlockState());
        setBlock(x + 6, y + 7, z + 12, CONCRETE);
        setBlock(x + 7, y + 7, z + 12, Blocks.AIR.defaultBlockState());
        setBlock(x + 8, y + 7, z + 12, CONCRETE);
        setBlock(x + 9, y + 7, z + 12, CONCRETE);
        setBlock(x + 11, y + 7, z + 12, CONCRETE);

        setBlock(x, y + 7, z + 13, CONCRETE);
        setBlock(x + 1, y + 7, z + 13, CONCRETE);
        setBlock(x + 2, y + 7, z + 13, CONCRETE);
        setBlock(x + 3, y + 7, z + 13, CONCRETE);
        setBlock(x + 4, y + 7, z + 13, CONCRETE);
        setBlock(x + 5, y + 7, z + 13, CONCRETE);
        setBlock(x + 6, y + 7, z + 13, CONCRETE);
        setBlock(x + 7, y + 7, z + 13, CONCRETE);
        setBlock(x + 8, y + 7, z + 13, CONCRETE);
        setBlock(x + 9, y + 7, z + 13, CONCRETE);
        setBlock(x + 10, y + 7, z + 13, CONCRETE);
        setBlock(x + 11, y + 7, z + 13, CONCRETE);

        setBlock(x + 1, y + 7, z + 14, CONCRETE);
        setBlock(x + 2, y + 7, z + 14, CONCRETE);
        setBlock(x + 3, y + 7, z + 14, CONCRETE);
        setBlock(x + 4, y + 7, z + 14, CONCRETE);
        setBlock(x + 5, y + 7, z + 14, CONCRETE);
        setBlock(x + 6, y + 7, z + 14, CONCRETE);
        setBlock(x + 7, y + 7, z + 14, CONCRETE);
        setBlock(x + 8, y + 7, z + 14, CONCRETE);
        setBlock(x + 9, y + 7, z + 14, CONCRETE);
        setBlock(x + 10, y + 7, z + 14, CONCRETE);
        setBlock(x + 11, y + 7, z + 14, CONCRETE);

        // Y+8
// stone_stairs метаданные 2 (facing north? подберём Direction)
        setBlock(x, y + 8, z + 1, Blocks.STONE_STAIRS.defaultBlockState().setValue(StairBlock.FACING, Direction.NORTH));
        setBlock(x + 1, y + 8, z + 1, Blocks.STONE_STAIRS.defaultBlockState().setValue(StairBlock.FACING, Direction.NORTH));
        setBlock(x + 2, y + 8, z + 1, Blocks.STONE_STAIRS.defaultBlockState().setValue(StairBlock.FACING, Direction.NORTH));
        setBlock(x + 3, y + 8, z + 1, Blocks.STONE_STAIRS.defaultBlockState().setValue(StairBlock.FACING, Direction.NORTH));
        setBlock(x + 4, y + 8, z + 1, Blocks.STONE_STAIRS.defaultBlockState().setValue(StairBlock.FACING, Direction.NORTH));
        setBlock(x + 5, y + 8, z + 1, Blocks.STONE_STAIRS.defaultBlockState().setValue(StairBlock.FACING, Direction.NORTH));
        setBlock(x + 6, y + 8, z + 1, Blocks.STONE_STAIRS.defaultBlockState().setValue(StairBlock.FACING, Direction.NORTH));
        setBlock(x + 7, y + 8, z + 1, Blocks.STONE_STAIRS.defaultBlockState().setValue(StairBlock.FACING, Direction.NORTH));
        setBlock(x + 8, y + 8, z + 1, Blocks.STONE_STAIRS.defaultBlockState().setValue(StairBlock.FACING, Direction.NORTH));
        setBlock(x + 9, y + 8, z + 1, Blocks.STONE_STAIRS.defaultBlockState().setValue(StairBlock.FACING, Direction.NORTH));
        setBlock(x + 10, y + 8, z + 1, Blocks.STONE_STAIRS.defaultBlockState().setValue(StairBlock.FACING, Direction.NORTH));
        setBlock(x + 11, y + 8, z + 1, Blocks.STONE_STAIRS.defaultBlockState().setValue(StairBlock.FACING, Direction.NORTH));

// stone_stairs метаданные 0 (facing south)
        setBlock(x, y + 8, z + 2, Blocks.STONE_STAIRS.defaultBlockState().setValue(StairBlock.FACING, Direction.SOUTH));
        setBlock(x + 1, y + 8, z + 2, COBBLESTONE);
        setBlock(x + 2, y + 8, z + 2, COBBLESTONE);
        setBlock(x + 3, y + 8, z + 2, MOSSY_COBBLESTONE);
        setBlock(x + 4, y + 8, z + 2, COBBLESTONE);
        setBlock(x + 5, y + 8, z + 2, COBBLESTONE);
        setBlock(x + 6, y + 8, z + 2, COBBLESTONE);
        setBlock(x + 7, y + 8, z + 2, COBBLESTONE);
        setBlock(x + 8, y + 8, z + 2, COBBLESTONE);
        setBlock(x + 9, y + 8, z + 2, COBBLESTONE);
        setBlock(x + 10, y + 8, z + 2, COBBLESTONE);
        setBlock(x + 11, y + 8, z + 2, COBBLESTONE);

// stone_stairs метаданные 0 (south), потом 1 (west), потом 3 (east)
        setBlock(x, y + 8, z + 3, Blocks.STONE_STAIRS.defaultBlockState().setValue(StairBlock.FACING, Direction.SOUTH));
        setBlock(x + 1, y + 8, z + 3, MOSSY_COBBLESTONE);
        setBlock(x + 2, y + 8, z + 3, COBBLESTONE);
        setBlock(x + 3, y + 8, z + 3, MOSSY_COBBLESTONE);
        setBlock(x + 4, y + 8, z + 3, MOSSY_COBBLESTONE);
        setBlock(x + 5, y + 8, z + 3, COBBLESTONE);
        setBlock(x + 6, y + 8, z + 3, STONE_SLAB); // метаданные 3 = stone slab верхний
        setBlock(x + 7, y + 8, z + 3, MOSSY_COBBLESTONE);
        setBlock(x + 8, y + 8, z + 3, Blocks.STONE_STAIRS.defaultBlockState().setValue(StairBlock.FACING, Direction.WEST));
        setBlock(x + 9, y + 8, z + 3, COBBLESTONE);
        setBlock(x + 10, y + 8, z + 3, Blocks.STONE_STAIRS.defaultBlockState().setValue(StairBlock.FACING, Direction.EAST));
        setBlock(x + 11, y + 8, z + 3, COBBLESTONE);

        setBlock(x, y + 8, z + 4, Blocks.STONE_STAIRS.defaultBlockState().setValue(StairBlock.FACING, Direction.SOUTH));
        setBlock(x + 1, y + 8, z + 4, COBBLESTONE);
        setBlock(x + 2, y + 8, z + 4, COBBLESTONE);
        setBlock(x + 3, y + 8, z + 4, COBBLESTONE);
        setBlock(x + 4, y + 8, z + 4, COBBLESTONE);
        setBlock(x + 5, y + 8, z + 4, COBBLESTONE);
        setBlock(x + 6, y + 8, z + 4, COBBLESTONE);
        setBlock(x + 7, y + 8, z + 4, COBBLESTONE);
        setBlock(x + 8, y + 8, z + 4, COBBLESTONE);
        setBlock(x + 9, y + 8, z + 4, COBBLESTONE);
        setBlock(x + 10, y + 8, z + 4, COBBLESTONE);
        setBlock(x + 11, y + 8, z + 4, COBBLESTONE);

        setBlock(x, y + 8, z + 5, DIRT);
        setBlock(x + 1, y + 8, z + 5, COBBLESTONE);
        setBlock(x + 2, y + 8, z + 5, COBBLESTONE);
        setBlock(x + 3, y + 8, z + 5, COBBLESTONE);
        setBlock(x + 4, y + 8, z + 5, COBBLESTONE);
        setBlock(x + 5, y + 8, z + 5, COBBLESTONE);
        setBlock(x + 6, y + 8, z + 5, COBBLESTONE);
        setBlock(x + 7, y + 8, z + 5, COBBLESTONE);
        setBlock(x + 8, y + 8, z + 5, COBBLESTONE);
        setBlock(x + 9, y + 8, z + 5, COBBLESTONE);
        setBlock(x + 10, y + 8, z + 5, COBBLESTONE);
        setBlock(x + 11, y + 8, z + 5, COBBLESTONE);

        setBlock(x, y + 8, z + 6, DIRT);
        setBlock(x + 1, y + 8, z + 6, COBBLESTONE);
        setBlock(x + 2, y + 8, z + 6, Blocks.BLACK_TERRACOTTA.defaultBlockState());  // stained_hardened_clay 15 = чёрный
        setBlock(x + 3, y + 8, z + 6, Blocks.WHITE_TERRACOTTA.defaultBlockState());    // 0 = белый
        setBlock(x + 4, y + 8, z + 6, Blocks.BLACK_TERRACOTTA.defaultBlockState());
        setBlock(x + 5, y + 8, z + 6, Blocks.SPRUCE_PLANKS.defaultBlockState());
        setBlock(x + 6, y + 8, z + 6, Blocks.SPRUCE_STAIRS.defaultBlockState().setValue(StairBlock.FACING, Direction.WEST));
        setBlock(x + 7, y + 8, z + 6, Blocks.SPRUCE_PLANKS.defaultBlockState());
        setBlock(x + 8, y + 8, z + 6, Blocks.SPRUCE_PLANKS.defaultBlockState());
        setBlock(x + 9, y + 8, z + 6, Blocks.SPRUCE_STAIRS.defaultBlockState().setValue(StairBlock.FACING, Direction.EAST));
        setBlock(x + 10, y + 8, z + 6, Blocks.SPRUCE_STAIRS.defaultBlockState().setValue(StairBlock.FACING, Direction.EAST));
        setBlock(x + 11, y + 8, z + 6, COBBLESTONE);

        setBlock(x, y + 8, z + 7, DIRT);
        setBlock(x + 1, y + 8, z + 7, COBBLESTONE);
        setBlock(x + 2, y + 8, z + 7, Blocks.WHITE_TERRACOTTA.defaultBlockState());
        setBlock(x + 3, y + 8, z + 7, Blocks.BLACK_TERRACOTTA.defaultBlockState());
        setBlock(x + 4, y + 8, z + 7, Blocks.WHITE_TERRACOTTA.defaultBlockState());
        setBlock(x + 5, y + 8, z + 7, Blocks.SPRUCE_PLANKS.defaultBlockState());
        setBlock(x + 6, y + 8, z + 7, Blocks.SPRUCE_STAIRS.defaultBlockState().setValue(StairBlock.FACING, Direction.WEST));
        setBlock(x + 7, y + 8, z + 7, Blocks.AIR.defaultBlockState());
        setBlock(x + 8, y + 8, z + 7, Blocks.AIR.defaultBlockState());
        setBlock(x + 9, y + 8, z + 7, Blocks.SPRUCE_STAIRS.defaultBlockState().setValue(StairBlock.FACING, Direction.SOUTH));
        setBlock(x + 10, y + 8, z + 7, Blocks.SPRUCE_STAIRS.defaultBlockState().setValue(StairBlock.FACING, Direction.SOUTH));
        setBlock(x + 11, y + 8, z + 7, Blocks.STONE_STAIRS.defaultBlockState().setValue(StairBlock.FACING, Direction.NORTH).setValue(BlockStateProperties.HALF, Half.TOP));

        setBlock(x, y + 8, z + 8, DIRT);
        setBlock(x + 1, y + 8, z + 8, COBBLESTONE);
        setBlock(x + 2, y + 8, z + 8, Blocks.BLACK_TERRACOTTA.defaultBlockState());
        setBlock(x + 3, y + 8, z + 8, Blocks.WHITE_TERRACOTTA.defaultBlockState());
        setBlock(x + 4, y + 8, z + 8, Blocks.BLACK_TERRACOTTA.defaultBlockState());
        setBlock(x + 5, y + 8, z + 8, Blocks.SPRUCE_PLANKS.defaultBlockState());
        setBlock(x + 6, y + 8, z + 8, Blocks.SPRUCE_PLANKS.defaultBlockState());
        setBlock(x + 7, y + 8, z + 8, Blocks.AIR.defaultBlockState());
        setBlock(x + 8, y + 8, z + 8, Blocks.AIR.defaultBlockState());
        setBlock(x + 9, y + 8, z + 8, Blocks.SPRUCE_PLANKS.defaultBlockState());
        setBlock(x + 10, y + 8, z + 8, Blocks.SPRUCE_SLAB.defaultBlockState());
        setBlock(x + 11, y + 8, z + 8, COBBLESTONE);

        setBlock(x, y + 8, z + 9, GRASS);
        setBlock(x + 1, y + 8, z + 9, COBBLESTONE);
        setBlock(x + 2, y + 8, z + 9, Blocks.WHITE_TERRACOTTA.defaultBlockState());
        setBlock(x + 3, y + 8, z + 9, Blocks.BLACK_TERRACOTTA.defaultBlockState());
        setBlock(x + 4, y + 8, z + 9, Blocks.WHITE_TERRACOTTA.defaultBlockState());
        setBlock(x + 5, y + 8, z + 9, Blocks.SPRUCE_STAIRS.defaultBlockState().setValue(StairBlock.FACING, Direction.WEST));
        setBlock(x + 6, y + 8, z + 9, Blocks.AIR.defaultBlockState());
        setBlock(x + 7, y + 8, z + 9, Blocks.AIR.defaultBlockState());
        setBlock(x + 8, y + 8, z + 9, Blocks.AIR.defaultBlockState());
        setBlock(x + 9, y + 8, z + 9, Blocks.SPRUCE_PLANKS.defaultBlockState());
        setBlock(x + 10, y + 8, z + 9, Blocks.SPRUCE_PLANKS.defaultBlockState());
        setBlock(x + 11, y + 8, z + 9, COBBLESTONE);

        setBlock(x, y + 8, z + 10, GRASS);
        setBlock(x + 1, y + 8, z + 10, COBBLESTONE);
        setBlock(x + 2, y + 8, z + 10, RED_CABLE);
        setBlock(x + 3, y + 8, z + 10, Blocks.WHITE_TERRACOTTA.defaultBlockState());
        setBlock(x + 4, y + 8, z + 10, Blocks.BLACK_TERRACOTTA.defaultBlockState());
        setBlock(x + 5, y + 8, z + 10, Blocks.AIR.defaultBlockState());
        setBlock(x + 6, y + 8, z + 10, Blocks.AIR.defaultBlockState());
        setBlock(x + 7, y + 8, z + 10, Blocks.AIR.defaultBlockState());
        setBlock(x + 8, y + 8, z + 10, Blocks.AIR.defaultBlockState());
        setBlock(x + 9, y + 8, z + 10, Blocks.SPRUCE_PLANKS.defaultBlockState());
        setBlock(x + 10, y + 8, z + 10, Blocks.SPRUCE_PLANKS.defaultBlockState());
        setBlock(x + 11, y + 8, z + 10, Blocks.STONE_STAIRS.defaultBlockState().setValue(StairBlock.FACING, Direction.WEST));

        setBlock(x, y + 8, z + 11, GRASS);
        setBlock(x + 1, y + 8, z + 11, COBBLESTONE);
        setBlock(x + 2, y + 8, z + 11, Blocks.WHITE_TERRACOTTA.defaultBlockState());
        setBlock(x + 3, y + 8, z + 11, Blocks.BLACK_TERRACOTTA.defaultBlockState());
        setBlock(x + 4, y + 8, z + 11, Blocks.AIR.defaultBlockState());
        setBlock(x + 5, y + 8, z + 11, Blocks.AIR.defaultBlockState());
        setBlock(x + 6, y + 8, z + 11, Blocks.AIR.defaultBlockState());
        setBlock(x + 7, y + 8, z + 11, Blocks.AIR.defaultBlockState());
        setBlock(x + 8, y + 8, z + 11, Blocks.AIR.defaultBlockState());
        setBlock(x + 9, y + 8, z + 11, Blocks.SPRUCE_PLANKS.defaultBlockState());
        setBlock(x + 10, y + 8, z + 11, Blocks.SPRUCE_PLANKS.defaultBlockState());
        setBlock(x + 11, y + 8, z + 11, COBBLESTONE);

        setBlock(x, y + 8, z + 12, GRASS);
        setBlock(x + 1, y + 8, z + 12, COBBLESTONE);
        setBlock(x + 2, y + 8, z + 12, RED_CABLE);
        setBlock(x + 3, y + 8, z + 12, Blocks.WHITE_TERRACOTTA.defaultBlockState());
        setBlock(x + 4, y + 8, z + 12, Blocks.BLACK_TERRACOTTA.defaultBlockState());
        setBlock(x + 5, y + 8, z + 12, Blocks.AIR.defaultBlockState());
        setBlock(x + 6, y + 8, z + 12, Blocks.SPRUCE_STAIRS.defaultBlockState().setValue(StairBlock.FACING, Direction.SOUTH));
        setBlock(x + 7, y + 8, z + 12, Blocks.SPRUCE_STAIRS.defaultBlockState().setValue(StairBlock.FACING, Direction.WEST));
        setBlock(x + 8, y + 8, z + 12, Blocks.SPRUCE_PLANKS.defaultBlockState());
        setBlock(x + 9, y + 8, z + 12, Blocks.SPRUCE_PLANKS.defaultBlockState());
        setBlock(x + 10, y + 8, z + 12, Blocks.OAK_TRAPDOOR.defaultBlockState().setValue(TrapDoorBlock.FACING, Direction.NORTH).setValue(TrapDoorBlock.OPEN, true));
        setBlock(x + 11, y + 8, z + 12, COBBLESTONE);

        setBlock(x, y + 8, z + 13, DIRT);
        setBlock(x + 1, y + 8, z + 13, COBBLESTONE);
        setBlock(x + 2, y + 8, z + 13, COBBLESTONE);
        setBlock(x + 3, y + 8, z + 13, MOSSY_COBBLESTONE);
        setBlock(x + 4, y + 8, z + 13, MOSSY_COBBLESTONE);
        setBlock(x + 5, y + 8, z + 13, MOSSY_COBBLESTONE);
        setBlock(x + 6, y + 8, z + 13, MOSSY_COBBLESTONE);
        setBlock(x + 7, y + 8, z + 13, COBBLESTONE);
        setBlock(x + 8, y + 8, z + 13, COBBLESTONE);
        setBlock(x + 9, y + 8, z + 13, COBBLESTONE);
        setBlock(x + 10, y + 8, z + 13, COBBLESTONE);
        setBlock(x + 11, y + 8, z + 13, MOSSY_COBBLESTONE);

        setBlock(x + 2, y + 8, z + 14, DIRT);
        setBlock(x + 3, y + 8, z + 14, GRASS);
        setBlock(x + 4, y + 8, z + 14, DIRT);
        setBlock(x + 5, y + 8, z + 14, DIRT);
        setBlock(x + 6, y + 8, z + 14, DIRT);
        setBlock(x + 7, y + 8, z + 14, GRASS);
        setBlock(x + 8, y + 8, z + 14, DIRT);
        setBlock(x + 9, y + 8, z + 14, DIRT);
        setBlock(x + 10, y + 8, z + 14, DIRT);
        setBlock(x + 11, y + 8, z + 14, DIRT);

        // Y+9
        setBlock(x, y + 9, z + 1, Blocks.AIR.defaultBlockState());
        setBlock(x + 1, y + 9, z + 1, Blocks.AIR.defaultBlockState());
        setBlock(x + 2, y + 9, z + 1, Blocks.AIR.defaultBlockState());
        setBlock(x + 3, y + 9, z + 1, Blocks.AIR.defaultBlockState());
        setBlock(x + 4, y + 9, z + 1, Blocks.AIR.defaultBlockState());
        setBlock(x + 5, y + 9, z + 1, Blocks.AIR.defaultBlockState());
        setBlock(x + 6, y + 9, z + 1, Blocks.AIR.defaultBlockState());
        setBlock(x + 7, y + 9, z + 1, Blocks.AIR.defaultBlockState());
        setBlock(x + 8, y + 9, z + 1, Blocks.AIR.defaultBlockState());
        setBlock(x + 9, y + 9, z + 1, Blocks.AIR.defaultBlockState());
        setBlock(x + 10, y + 9, z + 1, Blocks.AIR.defaultBlockState());
        setBlock(x + 11, y + 9, z + 1, Blocks.AIR.defaultBlockState());

        setBlock(x, y + 9, z + 2, Blocks.AIR.defaultBlockState());
        setBlock(x + 1, y + 9, z + 2, OAK_FENCE);
        setBlock(x + 2, y + 9, z + 2, Blocks.AIR.defaultBlockState());
        setBlock(x + 3, y + 9, z + 2, SPRUCE_SLAB);
        setBlock(x + 4, y + 9, z + 2, SPRUCE_PLANKS);
        setBlock(x + 5, y + 9, z + 2, SPRUCE_SLAB);
        setBlock(x + 6, y + 9, z + 2, Blocks.AIR.defaultBlockState());
        setBlock(x + 7, y + 9, z + 2, SPRUCE_SLAB);
        setBlock(x + 8, y + 9, z + 2, Blocks.AIR.defaultBlockState());
        setBlock(x + 9, y + 9, z + 2, SPRUCE_SLAB);
        setBlock(x + 10, y + 9, z + 2, SPRUCE_SLAB);
        setBlock(x + 11, y + 9, z + 2, OAK_FENCE);

        setBlock(x, y + 9, z + 3, Blocks.AIR.defaultBlockState());
        setBlock(x + 1, y + 9, z + 3, Blocks.AIR.defaultBlockState());
        setBlock(x + 2, y + 9, z + 3, SPRUCE_SLAB);
        setBlock(x + 3, y + 9, z + 3, SPRUCE_PLANKS);
        setBlock(x + 4, y + 9, z + 3, Blocks.AIR.defaultBlockState());
        setBlock(x + 5, y + 9, z + 3, OAK_FENCE);
        setBlock(x + 6, y + 9, z + 3, Blocks.AIR.defaultBlockState());
        setBlock(x + 7, y + 9, z + 3, OAK_FENCE);
        setBlock(x + 8, y + 9, z + 3, Blocks.AIR.defaultBlockState());
        setBlock(x + 9, y + 9, z + 3, SPRUCE_PLANKS);
        setBlock(x + 10, y + 9, z + 3, Blocks.AIR.defaultBlockState());
        setBlock(x + 11, y + 9, z + 3, Blocks.AIR.defaultBlockState());
        setBlock(x + 12, y + 9, z + 3, Blocks.AIR.defaultBlockState());

        setBlock(x, y + 9, z + 4, Blocks.AIR.defaultBlockState());
        setBlock(x + 1, y + 9, z + 4, Blocks.AIR.defaultBlockState());
        setBlock(x + 2, y + 9, z + 4, Blocks.AIR.defaultBlockState());
        setBlock(x + 3, y + 9, z + 4, Blocks.AIR.defaultBlockState());
        setBlock(x + 4, y + 9, z + 4, Blocks.AIR.defaultBlockState());
        setBlock(x + 5, y + 9, z + 4, Blocks.AIR.defaultBlockState());
        setBlock(x + 6, y + 9, z + 4, Blocks.AIR.defaultBlockState());
        setBlock(x + 7, y + 9, z + 4, Blocks.AIR.defaultBlockState());
        setBlock(x + 8, y + 9, z + 4, SPRUCE_PLANKS);
        setBlock(x + 9, y + 9, z + 4, Blocks.AIR.defaultBlockState());
        setBlock(x + 10, y + 9, z + 4, Blocks.AIR.defaultBlockState());
        setBlock(x + 11, y + 9, z + 4, Blocks.AIR.defaultBlockState());
        setBlock(x + 12, y + 9, z + 4, Blocks.AIR.defaultBlockState());

        setBlock(x, y + 9, z + 5, Blocks.AIR.defaultBlockState());
        setBlock(x + 1, y + 9, z + 5, MOSSY_COBBLESTONE);
        setBlock(x + 2, y + 9, z + 5, COBBLESTONE);
        setBlock(x + 3, y + 9, z + 5, COBBLESTONE);
        setBlock(x + 4, y + 9, z + 5, COBBLESTONE);
        setBlock(x + 5, y + 9, z + 5, COBBLESTONE);
        setBlock(x + 6, y + 9, z + 5, DIAMOND_BLOCK);
        setBlock(x + 7, y + 9, z + 5, COBBLESTONE);
        setBlock(x + 8, y + 9, z + 5, COBBLESTONE);
        setBlock(x + 9, y + 9, z + 5, COBBLESTONE);
        setBlock(x + 10, y + 9, z + 5, COBBLESTONE);
        setBlock(x + 11, y + 9, z + 5, COBBLESTONE);
        setBlock(x + 12, y + 9, z + 5, Blocks.AIR.defaultBlockState());

        setBlock(x, y + 9, z + 6, Blocks.AIR.defaultBlockState());
        setBlock(x + 1, y + 9, z + 6, MOSSY_COBBLESTONE);
        setBlock(x + 2, y + 9, z + 6, IRON_BLOCK);
        setBlock(x + 3, y + 9, z + 6, Blocks.IRON_DOOR.defaultBlockState().setValue(DoorBlock.FACING, Direction.NORTH).setValue(DoorBlock.HALF, DoubleBlockHalf.LOWER));
        setBlock(x + 4, y + 9, z + 6, DECO_STEEL);
        setBlock(x + 5, y + 9, z + 6, STEEL_WALL);
        setBlock(x + 6, y + 9, z + 6, Blocks.AIR.defaultBlockState());
        setBlock(x + 7, y + 9, z + 6, Blocks.AIR.defaultBlockState());
        setBlock(x + 8, y + 9, z + 6, Blocks.AIR.defaultBlockState());
        setBlock(x + 9, y + 9, z + 6, Blocks.AIR.defaultBlockState());
        setBlock(x + 10, y + 9, z + 6, Blocks.CHEST.defaultBlockState().setValue(ChestBlock.FACING, Direction.EAST));
        setBlock(x + 11, y + 9, z + 6, MOSSY_COBBLESTONE);
        setBlock(x + 12, y + 9, z + 6, Blocks.AIR.defaultBlockState());

        setBlock(x, y + 9, z + 7, Blocks.AIR.defaultBlockState());
        setBlock(x + 1, y + 9, z + 7, MOSSY_COBBLESTONE);
        setBlock(x + 2, y + 9, z + 7, DECO_STEEL);
        setBlock(x + 3, y + 9, z + 7, Blocks.AIR.defaultBlockState());
        setBlock(x + 4, y + 9, z + 7, DECO_STEEL);
        setBlock(x + 5, y + 9, z + 7, STEEL_WALL);
        setBlock(x + 6, y + 9, z + 7, Blocks.AIR.defaultBlockState());
        setBlock(x + 7, y + 9, z + 7, Blocks.AIR.defaultBlockState());
        setBlock(x + 8, y + 9, z + 7, Blocks.AIR.defaultBlockState());
        setBlock(x + 9, y + 9, z + 7, Blocks.AIR.defaultBlockState());
        setBlock(x + 10, y + 9, z + 7, Blocks.AIR.defaultBlockState());
        setBlock(x + 11, y + 9, z + 7, COBBLESTONE);
        setBlock(x + 12, y + 9, z + 7, Blocks.AIR.defaultBlockState());

        setBlock(x, y + 9, z + 8, Blocks.AIR.defaultBlockState());
        setBlock(x + 1, y + 9, z + 8, COBBLESTONE);
        setBlock(x + 2, y + 9, z + 8, CAULDRON);
        setBlock(x + 3, y + 9, z + 8, Blocks.AIR.defaultBlockState());
        setBlock(x + 4, y + 9, z + 8, DECO_STEEL);
        setBlock(x + 5, y + 9, z + 8, STEEL_WALL);
        setBlock(x + 6, y + 9, z + 8, Blocks.AIR.defaultBlockState());
        setBlock(x + 7, y + 9, z + 8, Blocks.AIR.defaultBlockState());
        setBlock(x + 8, y + 9, z + 8, Blocks.AIR.defaultBlockState());
        setBlock(x + 9, y + 9, z + 8, Blocks.AIR.defaultBlockState());
        setBlock(x + 10, y + 9, z + 8, Blocks.AIR.defaultBlockState());
        setBlock(x + 11, y + 9, z + 8, MOSSY_COBBLESTONE);
        setBlock(x + 12, y + 9, z + 8, Blocks.AIR.defaultBlockState());

        setBlock(x + 1, y + 9, z + 9, COBBLESTONE);
        setBlock(x + 2, y + 9, z + 9, DECO_STEEL);
        setBlock(x + 3, y + 9, z + 9, Blocks.AIR.defaultBlockState());
        setBlock(x + 4, y + 9, z + 9, DECO_STEEL);
        setBlock(x + 5, y + 9, z + 9, STEEL_WALL);
        setBlock(x + 6, y + 9, z + 9, Blocks.AIR.defaultBlockState());
        setBlock(x + 7, y + 9, z + 9, Blocks.AIR.defaultBlockState());
        setBlock(x + 8, y + 9, z + 9, Blocks.AIR.defaultBlockState());
        setBlock(x + 9, y + 9, z + 9, Blocks.AIR.defaultBlockState());
        setBlock(x + 10, y + 9, z + 9, Blocks.AIR.defaultBlockState());
        setBlock(x + 11, y + 9, z + 9, MOSSY_COBBLESTONE);
        setBlock(x + 12, y + 9, z + 9, Blocks.AIR.defaultBlockState());

        setBlock(x + 1, y + 9, z + 10, MOSSY_COBBLESTONE);
        setBlock(x + 2, y + 9, z + 10, Blocks.REDSTONE_LAMP.defaultBlockState().setValue(RedstoneLampBlock.LIT, true));
        setBlock(x + 3, y + 9, z + 10, Blocks.AIR.defaultBlockState());
        setBlock(x + 4, y + 9, z + 10, Blocks.AIR.defaultBlockState());
        setBlock(x + 5, y + 9, z + 10, Blocks.AIR.defaultBlockState());
        setBlock(x + 6, y + 9, z + 10, Blocks.AIR.defaultBlockState());
        setBlock(x + 7, y + 9, z + 10, Blocks.AIR.defaultBlockState());
        setBlock(x + 8, y + 9, z + 10, Blocks.AIR.defaultBlockState());
        setBlock(x + 9, y + 9, z + 10, Blocks.SPRUCE_STAIRS.defaultBlockState().setValue(StairBlock.FACING, Direction.WEST));
        setBlock(x + 10, y + 9, z + 10, Blocks.NETHER_BRICK_FENCE.defaultBlockState());
        setBlock(x + 11, y + 9, z + 10, MOSSY_COBBLESTONE);
        setBlock(x + 12, y + 9, z + 10, Blocks.AIR.defaultBlockState());

        setBlock(x + 1, y + 9, z + 11, MOSSY_COBBLESTONE);
        setBlock(x + 2, y + 9, z + 11, DECO_STEEL);
        setBlock(x + 3, y + 9, z + 11, Blocks.AIR.defaultBlockState());
        setBlock(x + 4, y + 9, z + 11, Blocks.AIR.defaultBlockState());
        setBlock(x + 5, y + 9, z + 11, Blocks.AIR.defaultBlockState());
        setBlock(x + 6, y + 9, z + 11, Blocks.AIR.defaultBlockState());
        setBlock(x + 7, y + 9, z + 11, Blocks.AIR.defaultBlockState());
        setBlock(x + 8, y + 9, z + 11, Blocks.AIR.defaultBlockState());
        setBlock(x + 9, y + 9, z + 11, Blocks.SPRUCE_STAIRS.defaultBlockState().setValue(StairBlock.FACING, Direction.WEST));
        setBlock(x + 10, y + 9, z + 11, Blocks.NETHER_BRICK_FENCE.defaultBlockState());
        setBlock(x + 11, y + 9, z + 11, COBBLESTONE);
        setBlock(x + 12, y + 9, z + 11, Blocks.AIR.defaultBlockState());

        setBlock(x + 1, y + 9, z + 12, MOSSY_COBBLESTONE);
        setBlock(x + 2, y + 9, z + 12, Blocks.REDSTONE_LAMP.defaultBlockState().setValue(RedstoneLampBlock.LIT, true));
        setBlock(x + 3, y + 9, z + 12, Blocks.AIR.defaultBlockState());
        setBlock(x + 4, y + 9, z + 12, Blocks.AIR.defaultBlockState());
        setBlock(x + 5, y + 9, z + 12, Blocks.AIR.defaultBlockState());
        setBlock(x + 6, y + 9, z + 12, Blocks.AIR.defaultBlockState());
        setBlock(x + 7, y + 9, z + 12, Blocks.AIR.defaultBlockState());
        setBlock(x + 8, y + 9, z + 12, Blocks.AIR.defaultBlockState());
        setBlock(x + 9, y + 9, z + 12, Blocks.AIR.defaultBlockState());
        setBlock(x + 10, y + 9, z + 12, Blocks.AIR.defaultBlockState());
        setBlock(x + 11, y + 9, z + 12, Blocks.STONE_STAIRS.defaultBlockState().setValue(StairBlock.FACING, Direction.NORTH).setValue(BlockStateProperties.HALF, Half.TOP));
        setBlock(x + 12, y + 9, z + 12, Blocks.AIR.defaultBlockState());

        setBlock(x, y + 9, z + 13, Blocks.AIR.defaultBlockState());
        setBlock(x + 1, y + 9, z + 13, COBBLESTONE);
        setBlock(x + 2, y + 9, z + 13, COBBLESTONE);
        setBlock(x + 3, y + 9, z + 13, COBBLESTONE);
        setBlock(x + 4, y + 9, z + 13, Blocks.STONE_STAIRS.defaultBlockState().setValue(StairBlock.FACING, Direction.EAST));
        setBlock(x + 5, y + 9, z + 13, MOSSY_COBBLESTONE);
        setBlock(x + 6, y + 9, z + 13, MOSSY_COBBLESTONE);
        setBlock(x + 7, y + 9, z + 13, COBBLESTONE);
        setBlock(x + 8, y + 9, z + 13, MOSSY_COBBLESTONE);
        setBlock(x + 9, y + 9, z + 13, MOSSY_COBBLESTONE);
        setBlock(x + 10, y + 9, z + 13, MOSSY_COBBLESTONE);
        setBlock(x + 11, y + 9, z + 13, COBBLESTONE);
        setBlock(x + 12, y + 9, z + 13, Blocks.AIR.defaultBlockState());

        setBlock(x + 1, y + 9, z + 14, Blocks.AIR.defaultBlockState());
        setBlock(x + 2, y + 9, z + 14, Blocks.AIR.defaultBlockState());
        setBlock(x + 4, y + 9, z + 14, Blocks.AIR.defaultBlockState());
        setBlock(x + 5, y + 9, z + 14, Blocks.AIR.defaultBlockState());
        setBlock(x + 6, y + 9, z + 14, Blocks.AIR.defaultBlockState());
        setBlock(x + 8, y + 9, z + 14, Blocks.AIR.defaultBlockState());
        setBlock(x + 9, y + 9, z + 14, Blocks.AIR.defaultBlockState());
        setBlock(x + 10, y + 9, z + 14, Blocks.AIR.defaultBlockState());
        setBlock(x + 11, y + 9, z + 14, Blocks.AIR.defaultBlockState());

// Y+10
        setBlock(x, y + 10, z + 1, Blocks.AIR.defaultBlockState());
        setBlock(x + 1, y + 10, z + 1, Blocks.AIR.defaultBlockState());
        setBlock(x + 2, y + 10, z + 1, Blocks.AIR.defaultBlockState());
        setBlock(x + 3, y + 10, z + 1, Blocks.AIR.defaultBlockState());
        setBlock(x + 4, y + 10, z + 1, Blocks.AIR.defaultBlockState());
        setBlock(x + 5, y + 10, z + 1, Blocks.AIR.defaultBlockState());
        setBlock(x + 6, y + 10, z + 1, Blocks.AIR.defaultBlockState());
        setBlock(x + 7, y + 10, z + 1, Blocks.AIR.defaultBlockState());
        setBlock(x + 8, y + 10, z + 1, Blocks.AIR.defaultBlockState());
        setBlock(x + 9, y + 10, z + 1, Blocks.AIR.defaultBlockState());
        setBlock(x + 10, y + 10, z + 1, Blocks.AIR.defaultBlockState());
        setBlock(x + 11, y + 10, z + 1, Blocks.AIR.defaultBlockState());

        setBlock(x, y + 10, z + 2, Blocks.AIR.defaultBlockState());
        setBlock(x + 1, y + 10, z + 2, OAK_FENCE);
        setBlock(x + 2, y + 10, z + 2, Blocks.AIR.defaultBlockState());
        setBlock(x + 3, y + 10, z + 2, Blocks.AIR.defaultBlockState());
        setBlock(x + 4, y + 10, z + 2, Blocks.AIR.defaultBlockState());
        setBlock(x + 5, y + 10, z + 2, Blocks.AIR.defaultBlockState());
        setBlock(x + 6, y + 10, z + 2, Blocks.AIR.defaultBlockState());
        setBlock(x + 7, y + 10, z + 2, Blocks.AIR.defaultBlockState());
        setBlock(x + 8, y + 10, z + 2, Blocks.AIR.defaultBlockState());
        setBlock(x + 9, y + 10, z + 2, Blocks.AIR.defaultBlockState());
        setBlock(x + 10, y + 10, z + 2, Blocks.AIR.defaultBlockState());
        setBlock(x + 11, y + 10, z + 2, OAK_FENCE);

        setBlock(x, y + 10, z + 3, Blocks.AIR.defaultBlockState());
        setBlock(x + 1, y + 10, z + 3, Blocks.AIR.defaultBlockState());
        setBlock(x + 2, y + 10, z + 3, Blocks.AIR.defaultBlockState());
        setBlock(x + 3, y + 10, z + 3, Blocks.AIR.defaultBlockState());
        setBlock(x + 4, y + 10, z + 3, Blocks.AIR.defaultBlockState());
        setBlock(x + 5, y + 10, z + 3, OAK_FENCE);
        setBlock(x + 6, y + 10, z + 3, Blocks.AIR.defaultBlockState());
        setBlock(x + 7, y + 10, z + 3, OAK_FENCE);
        setBlock(x + 8, y + 10, z + 3, Blocks.AIR.defaultBlockState());
        setBlock(x + 9, y + 10, z + 3, SPRUCE_SLAB);
        setBlock(x + 10, y + 10, z + 3, Blocks.AIR.defaultBlockState());
        setBlock(x + 11, y + 10, z + 3, Blocks.AIR.defaultBlockState());
        setBlock(x + 12, y + 10, z + 3, Blocks.AIR.defaultBlockState());

        setBlock(x, y + 10, z + 4, Blocks.AIR.defaultBlockState());
        setBlock(x + 1, y + 10, z + 4, Blocks.AIR.defaultBlockState());
        setBlock(x + 2, y + 10, z + 4, Blocks.AIR.defaultBlockState());
        setBlock(x + 3, y + 10, z + 4, Blocks.AIR.defaultBlockState());
        setBlock(x + 4, y + 10, z + 4, Blocks.AIR.defaultBlockState());
        setBlock(x + 5, y + 10, z + 4, Blocks.AIR.defaultBlockState());
        setBlock(x + 6, y + 10, z + 4, Blocks.AIR.defaultBlockState());
        setBlock(x + 7, y + 10, z + 4, Blocks.AIR.defaultBlockState());
        setBlock(x + 8, y + 10, z + 4, Blocks.AIR.defaultBlockState());
        setBlock(x + 9, y + 10, z + 4, Blocks.AIR.defaultBlockState());
        setBlock(x + 10, y + 10, z + 4, Blocks.AIR.defaultBlockState());
        setBlock(x + 11, y + 10, z + 4, Blocks.AIR.defaultBlockState());
        setBlock(x + 12, y + 10, z + 4, Blocks.AIR.defaultBlockState());

        setBlock(x, y + 10, z + 5, Blocks.AIR.defaultBlockState());
        setBlock(x + 1, y + 10, z + 5, COBBLESTONE);
        setBlock(x + 2, y + 10, z + 5, Blocks.STONE_STAIRS.defaultBlockState().setValue(StairBlock.FACING, Direction.NORTH));
        setBlock(x + 3, y + 10, z + 5, Blocks.STONE_STAIRS.defaultBlockState().setValue(StairBlock.FACING, Direction.NORTH));
        setBlock(x + 4, y + 10, z + 5, STONE_SLAB);
        setBlock(x + 5, y + 10, z + 5, COBBLESTONE);
        setBlock(x + 6, y + 10, z + 5, DIAMOND_BLOCK);
        setBlock(x + 7, y + 10, z + 5, Blocks.STONE_STAIRS.defaultBlockState().setValue(StairBlock.FACING, Direction.NORTH));
        setBlock(x + 8, y + 10, z + 5, Blocks.AIR.defaultBlockState());
        setBlock(x + 9, y + 10, z + 5, STONE_SLAB);
        setBlock(x + 10, y + 10, z + 5, COBBLESTONE);
        setBlock(x + 11, y + 10, z + 5, COBBLESTONE);
        setBlock(x + 12, y + 10, z + 5, Blocks.AIR.defaultBlockState());

        setBlock(x, y + 10, z + 6, Blocks.AIR.defaultBlockState());
        setBlock(x + 1, y + 10, z + 6, COBBLESTONE);
        setBlock(x + 2, y + 10, z + 6, Blocks.DISPENSER.defaultBlockState().setValue(DispenserBlock.FACING, Direction.SOUTH));
        setBlock(x + 3, y + 10, z + 6, Blocks.IRON_DOOR.defaultBlockState().setValue(DoorBlock.FACING, Direction.SOUTH).setValue(DoorBlock.HALF, DoubleBlockHalf.UPPER));
        setBlock(x + 4, y + 10, z + 6, Blocks.FLOWER_POT.defaultBlockState());
        setBlock(x + 5, y + 10, z + 6, Blocks.AIR.defaultBlockState());
        setBlock(x + 6, y + 10, z + 6, Blocks.AIR.defaultBlockState());
        setBlock(x + 7, y + 10, z + 6, Blocks.AIR.defaultBlockState());
        setBlock(x + 8, y + 10, z + 6, Blocks.AIR.defaultBlockState());
        setBlock(x + 9, y + 10, z + 6, Blocks.AIR.defaultBlockState());
        setBlock(x + 10, y + 10, z + 6, Blocks.AIR.defaultBlockState());
        setBlock(x + 11, y + 10, z + 6, COBBLESTONE);
        setBlock(x + 12, y + 10, z + 6, Blocks.AIR.defaultBlockState());

        setBlock(x, y + 10, z + 7, Blocks.AIR.defaultBlockState());
        setBlock(x + 1, y + 10, z + 7, COBBLESTONE);
        setBlock(x + 3, y + 10, z + 7, Blocks.AIR.defaultBlockState());
        setBlock(x + 4, y + 10, z + 7, Blocks.AIR.defaultBlockState());
        setBlock(x + 5, y + 10, z + 7, Blocks.AIR.defaultBlockState());
        setBlock(x + 6, y + 10, z + 7, Blocks.AIR.defaultBlockState());
        setBlock(x + 7, y + 10, z + 7, Blocks.AIR.defaultBlockState());
        setBlock(x + 8, y + 10, z + 7, Blocks.AIR.defaultBlockState());
        setBlock(x + 9, y + 10, z + 7, Blocks.AIR.defaultBlockState());
        setBlock(x + 11, y + 10, z + 7, COBBLESTONE);
        setBlock(x + 12, y + 10, z + 7, Blocks.AIR.defaultBlockState());

        setBlock(x, y + 10, z + 8, Blocks.AIR.defaultBlockState());
        setBlock(x + 1, y + 10, z + 8, COBBLESTONE);
        setBlock(x + 3, y + 10, z + 8, Blocks.AIR.defaultBlockState());
        setBlock(x + 4, y + 10, z + 8, Blocks.AIR.defaultBlockState());
        setBlock(x + 5, y + 10, z + 8, Blocks.AIR.defaultBlockState());
        setBlock(x + 6, y + 10, z + 8, Blocks.AIR.defaultBlockState());
        setBlock(x + 7, y + 10, z + 8, Blocks.AIR.defaultBlockState());
        setBlock(x + 8, y + 10, z + 8, Blocks.AIR.defaultBlockState());
        setBlock(x + 9, y + 10, z + 8, Blocks.AIR.defaultBlockState());
        setBlock(x + 10, y + 10, z + 8, Blocks.AIR.defaultBlockState());
        setBlock(x + 11, y + 10, z + 8, Blocks.STONE_STAIRS.defaultBlockState().setValue(StairBlock.FACING, Direction.NORTH).setValue(BlockStateProperties.HALF, Half.TOP));
        setBlock(x + 12, y + 10, z + 8, Blocks.AIR.defaultBlockState());

        setBlock(x, y + 10, z + 9, Blocks.AIR.defaultBlockState());
        setBlock(x + 1, y + 10, z + 9, COBBLESTONE);
        setBlock(x + 3, y + 10, z + 9, Blocks.AIR.defaultBlockState());
        setBlock(x + 4, y + 10, z + 9, Blocks.AIR.defaultBlockState());
        setBlock(x + 5, y + 10, z + 9, Blocks.AIR.defaultBlockState());
        setBlock(x + 6, y + 10, z + 9, Blocks.AIR.defaultBlockState());
        setBlock(x + 7, y + 10, z + 9, Blocks.AIR.defaultBlockState());
        setBlock(x + 8, y + 10, z + 9, Blocks.AIR.defaultBlockState());
        setBlock(x + 9, y + 10, z + 9, Blocks.AIR.defaultBlockState());
        setBlock(x + 10, y + 10, z + 9, Blocks.AIR.defaultBlockState());
        setBlock(x + 11, y + 10, z + 9, Blocks.STONE_STAIRS.defaultBlockState().setValue(StairBlock.FACING, Direction.SOUTH));
        setBlock(x + 12, y + 10, z + 9, Blocks.AIR.defaultBlockState());

        setBlock(x + 1, y + 10, z + 10, STONE_SLAB);
        setBlock(x + 2, y + 10, z + 10, Blocks.AIR.defaultBlockState());
        setBlock(x + 3, y + 10, z + 10, Blocks.AIR.defaultBlockState());
        setBlock(x + 4, y + 10, z + 10, Blocks.AIR.defaultBlockState());
        setBlock(x + 5, y + 10, z + 10, Blocks.AIR.defaultBlockState());
        setBlock(x + 6, y + 10, z + 10, Blocks.AIR.defaultBlockState());
        setBlock(x + 7, y + 10, z + 10, Blocks.AIR.defaultBlockState());
        setBlock(x + 8, y + 10, z + 10, Blocks.AIR.defaultBlockState());
        setBlock(x + 9, y + 10, z + 10, Blocks.AIR.defaultBlockState());
        setBlock(x + 10, y + 10, z + 10, SPRUCE_SLAB);
        setBlock(x + 11, y + 10, z + 10, Blocks.STONE_STAIRS.defaultBlockState().setValue(StairBlock.FACING, Direction.NORTH).setValue(BlockStateProperties.HALF, Half.TOP));
        setBlock(x + 12, y + 10, z + 10, Blocks.AIR.defaultBlockState());

        setBlock(x, y + 10, z + 11, Blocks.AIR.defaultBlockState());
        setBlock(x + 1, y + 10, z + 11, COBBLESTONE);
        setBlock(x + 2, y + 10, z + 11, Blocks.AIR.defaultBlockState());
        setBlock(x + 3, y + 10, z + 11, Blocks.AIR.defaultBlockState());
        setBlock(x + 4, y + 10, z + 11, Blocks.AIR.defaultBlockState());
        setBlock(x + 5, y + 10, z + 11, Blocks.AIR.defaultBlockState());
        setBlock(x + 6, y + 10, z + 11, Blocks.AIR.defaultBlockState());
        setBlock(x + 7, y + 10, z + 11, Blocks.AIR.defaultBlockState());
        setBlock(x + 8, y + 10, z + 11, Blocks.AIR.defaultBlockState());
        setBlock(x + 9, y + 10, z + 11, Blocks.AIR.defaultBlockState());
        setBlock(x + 10, y + 10, z + 11, SPRUCE_SLAB);
        setBlock(x + 11, y + 10, z + 11, COBBLESTONE);
        setBlock(x + 12, y + 10, z + 11, Blocks.AIR.defaultBlockState());

        setBlock(x, y + 10, z + 12, Blocks.AIR.defaultBlockState());
        setBlock(x + 1, y + 10, z + 12, COBBLESTONE);
        setBlock(x + 2, y + 10, z + 12, Blocks.AIR.defaultBlockState());
        setBlock(x + 3, y + 10, z + 12, Blocks.AIR.defaultBlockState());
        setBlock(x + 4, y + 10, z + 12, Blocks.AIR.defaultBlockState());
        setBlock(x + 5, y + 10, z + 12, Blocks.AIR.defaultBlockState());
        setBlock(x + 6, y + 10, z + 12, Blocks.AIR.defaultBlockState());
        setBlock(x + 7, y + 10, z + 12, Blocks.AIR.defaultBlockState());
        setBlock(x + 8, y + 10, z + 12, Blocks.AIR.defaultBlockState());
        setBlock(x + 9, y + 10, z + 12, Blocks.AIR.defaultBlockState());
        setBlock(x + 10, y + 10, z + 12, Blocks.AIR.defaultBlockState());
        setBlock(x + 11, y + 10, z + 12, STONE_SLAB);
        setBlock(x + 12, y + 10, z + 12, Blocks.AIR.defaultBlockState());

        setBlock(x, y + 10, z + 13, Blocks.AIR.defaultBlockState());
        setBlock(x + 1, y + 10, z + 13, COBBLESTONE);
        setBlock(x + 2, y + 10, z + 13, COBBLESTONE);
        setBlock(x + 3, y + 10, z + 13, Blocks.STONE_STAIRS.defaultBlockState().setValue(StairBlock.FACING, Direction.EAST).setValue(BlockStateProperties.HALF, Half.TOP));
        setBlock(x + 4, y + 10, z + 13, COBBLESTONE);
        setBlock(x + 5, y + 10, z + 13, Blocks.GLASS.defaultBlockState());
        setBlock(x + 6, y + 10, z + 13, Blocks.AIR.defaultBlockState());
        setBlock(x + 7, y + 10, z + 13, Blocks.GLASS.defaultBlockState());
        setBlock(x + 8, y + 10, z + 13, COBBLESTONE);
        setBlock(x + 9, y + 10, z + 13, COBBLESTONE);
        setBlock(x + 10, y + 10, z + 13, COBBLESTONE);
        setBlock(x + 11, y + 10, z + 13, COBBLESTONE);
        setBlock(x + 12, y + 10, z + 13, Blocks.AIR.defaultBlockState());

        setBlock(x + 1, y + 10, z + 14, Blocks.AIR.defaultBlockState());
        setBlock(x + 2, y + 10, z + 14, Blocks.AIR.defaultBlockState());
        setBlock(x + 3, y + 10, z + 14, Blocks.AIR.defaultBlockState());
        setBlock(x + 4, y + 10, z + 14, Blocks.AIR.defaultBlockState());
        setBlock(x + 5, y + 10, z + 14, Blocks.AIR.defaultBlockState());
        setBlock(x + 6, y + 10, z + 14, Blocks.AIR.defaultBlockState());
        setBlock(x + 7, y + 10, z + 14, Blocks.AIR.defaultBlockState());
        setBlock(x + 8, y + 10, z + 14, Blocks.AIR.defaultBlockState());
        setBlock(x + 9, y + 10, z + 14, Blocks.AIR.defaultBlockState());
        setBlock(x + 10, y + 10, z + 14, Blocks.AIR.defaultBlockState());
        setBlock(x + 11, y + 10, z + 14, Blocks.AIR.defaultBlockState());

        // Y+11
        setBlock(x, y + 11, z + 1, Blocks.AIR.defaultBlockState());
        setBlock(x + 1, y + 11, z + 1, Blocks.AIR.defaultBlockState());
        setBlock(x + 2, y + 11, z + 1, Blocks.AIR.defaultBlockState());
        setBlock(x + 3, y + 11, z + 1, Blocks.AIR.defaultBlockState());
        setBlock(x + 4, y + 11, z + 1, Blocks.AIR.defaultBlockState());
        setBlock(x + 5, y + 11, z + 1, Blocks.AIR.defaultBlockState());
        setBlock(x + 6, y + 11, z + 1, Blocks.AIR.defaultBlockState());
        setBlock(x + 7, y + 11, z + 1, Blocks.AIR.defaultBlockState());
        setBlock(x + 8, y + 11, z + 1, Blocks.AIR.defaultBlockState());
        setBlock(x + 9, y + 11, z + 1, Blocks.AIR.defaultBlockState());
        setBlock(x + 10, y + 11, z + 1, Blocks.AIR.defaultBlockState());
        setBlock(x + 11, y + 11, z + 1, Blocks.AIR.defaultBlockState());

        setBlock(x, y + 11, z + 2, Blocks.AIR.defaultBlockState());
        setBlock(x + 1, y + 11, z + 2, OAK_FENCE);
        setBlock(x + 2, y + 11, z + 2, Blocks.AIR.defaultBlockState());
        setBlock(x + 3, y + 11, z + 2, Blocks.AIR.defaultBlockState());
        setBlock(x + 4, y + 11, z + 2, Blocks.AIR.defaultBlockState());
        setBlock(x + 5, y + 11, z + 2, Blocks.AIR.defaultBlockState());
        setBlock(x + 6, y + 11, z + 2, Blocks.AIR.defaultBlockState());
        setBlock(x + 7, y + 11, z + 2, Blocks.AIR.defaultBlockState());
        setBlock(x + 8, y + 11, z + 2, Blocks.AIR.defaultBlockState());
        setBlock(x + 9, y + 11, z + 2, Blocks.AIR.defaultBlockState());
        setBlock(x + 10, y + 11, z + 2, Blocks.AIR.defaultBlockState());
        setBlock(x + 11, y + 11, z + 2, OAK_FENCE);

        setBlock(x, y + 11, z + 3, Blocks.AIR.defaultBlockState());
        setBlock(x + 1, y + 11, z + 3, Blocks.AIR.defaultBlockState());
        setBlock(x + 2, y + 11, z + 3, Blocks.AIR.defaultBlockState());
        setBlock(x + 3, y + 11, z + 3, Blocks.AIR.defaultBlockState());
        setBlock(x + 4, y + 11, z + 3, Blocks.AIR.defaultBlockState());
        setBlock(x + 5, y + 11, z + 3, OAK_FENCE);
        setBlock(x + 6, y + 11, z + 3, Blocks.AIR.defaultBlockState());
        setBlock(x + 7, y + 11, z + 3, OAK_FENCE);
        setBlock(x + 8, y + 11, z + 3, Blocks.AIR.defaultBlockState());
        setBlock(x + 9, y + 11, z + 3, Blocks.AIR.defaultBlockState());
        setBlock(x + 10, y + 11, z + 3, Blocks.AIR.defaultBlockState());
        setBlock(x + 11, y + 11, z + 3, Blocks.AIR.defaultBlockState());
        setBlock(x + 12, y + 11, z + 3, Blocks.AIR.defaultBlockState());

        setBlock(x, y + 11, z + 4, Blocks.AIR.defaultBlockState());
        setBlock(x + 1, y + 11, z + 4, Blocks.AIR.defaultBlockState());
        setBlock(x + 2, y + 11, z + 4, Blocks.AIR.defaultBlockState());
        setBlock(x + 3, y + 11, z + 4, Blocks.AIR.defaultBlockState());
        setBlock(x + 4, y + 11, z + 4, Blocks.AIR.defaultBlockState());
        setBlock(x + 5, y + 11, z + 4, Blocks.AIR.defaultBlockState());
        setBlock(x + 6, y + 11, z + 4, Blocks.AIR.defaultBlockState());
        setBlock(x + 7, y + 11, z + 4, Blocks.AIR.defaultBlockState());
        setBlock(x + 8, y + 11, z + 4, Blocks.AIR.defaultBlockState());
        setBlock(x + 9, y + 11, z + 4, Blocks.AIR.defaultBlockState());
        setBlock(x + 10, y + 11, z + 4, Blocks.AIR.defaultBlockState());
        setBlock(x + 11, y + 11, z + 4, Blocks.AIR.defaultBlockState());
        setBlock(x + 12, y + 11, z + 4, Blocks.AIR.defaultBlockState());

        setBlock(x, y + 11, z + 5, Blocks.AIR.defaultBlockState());
        setBlock(x + 1, y + 11, z + 5, COBBLESTONE);
        setBlock(x + 2, y + 11, z + 5, COBBLESTONE);
        setBlock(x + 3, y + 11, z + 5, Blocks.STONE_STAIRS.defaultBlockState().setValue(StairBlock.FACING, Direction.NORTH).setValue(BlockStateProperties.HALF, Half.TOP));
        setBlock(x + 4, y + 11, z + 5, COBBLESTONE);
        setBlock(x + 5, y + 11, z + 5, COBBLESTONE);
        setBlock(x + 6, y + 11, z + 5, COBBLESTONE);
        setBlock(x + 7, y + 11, z + 5, COBBLESTONE);
        setBlock(x + 8, y + 11, z + 5, COBBLESTONE);
        setBlock(x + 9, y + 11, z + 5, Blocks.STONE_STAIRS.defaultBlockState().setValue(StairBlock.FACING, Direction.NORTH));
        setBlock(x + 10, y + 11, z + 5, COBBLESTONE);
        setBlock(x + 11, y + 11, z + 5, COBBLESTONE);
        setBlock(x + 12, y + 11, z + 5, Blocks.AIR.defaultBlockState());

        setBlock(x, y + 11, z + 6, Blocks.AIR.defaultBlockState());
        setBlock(x + 1, y + 11, z + 6, COBBLESTONE);
        setBlock(x + 2, y + 11, z + 6, Blocks.AIR.defaultBlockState());
        setBlock(x + 3, y + 11, z + 6, Blocks.AIR.defaultBlockState());
        setBlock(x + 4, y + 11, z + 6, Blocks.AIR.defaultBlockState());
        setBlock(x + 5, y + 11, z + 6, Blocks.AIR.defaultBlockState());
        setBlock(x + 6, y + 11, z + 6, Blocks.AIR.defaultBlockState());
        setBlock(x + 7, y + 11, z + 6, Blocks.AIR.defaultBlockState());
        setBlock(x + 8, y + 11, z + 6, Blocks.AIR.defaultBlockState());
        setBlock(x + 9, y + 11, z + 6, Blocks.AIR.defaultBlockState());
        setBlock(x + 10, y + 11, z + 6, Blocks.AIR.defaultBlockState());
        setBlock(x + 11, y + 11, z + 6, STONE_SLAB);
        setBlock(x + 12, y + 11, z + 6, Blocks.AIR.defaultBlockState());

        setBlock(x, y + 11, z + 7, Blocks.AIR.defaultBlockState());
        setBlock(x + 1, y + 11, z + 7, COBBLESTONE);
        setBlock(x + 2, y + 11, z + 7, Blocks.AIR.defaultBlockState());
        setBlock(x + 3, y + 11, z + 7, Blocks.AIR.defaultBlockState());
        setBlock(x + 4, y + 11, z + 7, Blocks.AIR.defaultBlockState());
        setBlock(x + 5, y + 11, z + 7, Blocks.AIR.defaultBlockState());
        setBlock(x + 6, y + 11, z + 7, Blocks.AIR.defaultBlockState());
        setBlock(x + 7, y + 11, z + 7, Blocks.AIR.defaultBlockState());
        setBlock(x + 8, y + 11, z + 7, Blocks.AIR.defaultBlockState());
        setBlock(x + 9, y + 11, z + 7, Blocks.AIR.defaultBlockState());
        setBlock(x + 10, y + 11, z + 7, Blocks.AIR.defaultBlockState());
        setBlock(x + 11, y + 11, z + 7, STONE_SLAB);
        setBlock(x + 12, y + 11, z + 7, Blocks.AIR.defaultBlockState());

        setBlock(x, y + 11, z + 8, Blocks.AIR.defaultBlockState());
        setBlock(x + 1, y + 11, z + 8, COBBLESTONE);
        setBlock(x + 2, y + 11, z + 8, Blocks.AIR.defaultBlockState());
        setBlock(x + 3, y + 11, z + 8, Blocks.AIR.defaultBlockState());
        setBlock(x + 4, y + 11, z + 8, Blocks.AIR.defaultBlockState());
        setBlock(x + 5, y + 11, z + 8, Blocks.AIR.defaultBlockState());
        setBlock(x + 6, y + 11, z + 8, Blocks.AIR.defaultBlockState());
        setBlock(x + 7, y + 11, z + 8, Blocks.AIR.defaultBlockState());
        setBlock(x + 8, y + 11, z + 8, Blocks.AIR.defaultBlockState());
        setBlock(x + 9, y + 11, z + 8, Blocks.AIR.defaultBlockState());
        setBlock(x + 10, y + 11, z + 8, Blocks.AIR.defaultBlockState());
        setBlock(x + 11, y + 11, z + 8, COBBLESTONE);
        setBlock(x + 12, y + 11, z + 8, Blocks.AIR.defaultBlockState());

        setBlock(x, y + 11, z + 9, Blocks.AIR.defaultBlockState());
        setBlock(x + 1, y + 11, z + 9, Blocks.STONE_STAIRS.defaultBlockState().setValue(StairBlock.FACING, Direction.SOUTH));
        setBlock(x + 2, y + 11, z + 9, Blocks.TRAPPED_CHEST.defaultBlockState().setValue(ChestBlock.FACING, Direction.WEST));
        setBlock(x + 3, y + 11, z + 9, Blocks.AIR.defaultBlockState());
        setBlock(x + 4, y + 11, z + 9, Blocks.AIR.defaultBlockState());
        setBlock(x + 5, y + 11, z + 9, Blocks.AIR.defaultBlockState());
        setBlock(x + 6, y + 11, z + 9, Blocks.AIR.defaultBlockState());
        setBlock(x + 7, y + 11, z + 9, Blocks.AIR.defaultBlockState());
        setBlock(x + 8, y + 11, z + 9, Blocks.AIR.defaultBlockState());
        setBlock(x + 9, y + 11, z + 9, Blocks.AIR.defaultBlockState());
        setBlock(x + 10, y + 11, z + 9, Blocks.AIR.defaultBlockState());
        setBlock(x + 11, y + 11, z + 9, COBBLESTONE);
        setBlock(x + 12, y + 11, z + 9, Blocks.AIR.defaultBlockState());

        setBlock(x, y + 11, z + 10, Blocks.AIR.defaultBlockState());
        setBlock(x + 1, y + 11, z + 10, COBBLESTONE);
        setBlock(x + 2, y + 11, z + 10, Blocks.CHEST.defaultBlockState().setValue(ChestBlock.FACING, Direction.WEST));
        setBlock(x + 3, y + 11, z + 10, Blocks.AIR.defaultBlockState());
        setBlock(x + 4, y + 11, z + 10, Blocks.AIR.defaultBlockState());
        setBlock(x + 5, y + 11, z + 10, Blocks.AIR.defaultBlockState());
        setBlock(x + 6, y + 11, z + 10, Blocks.AIR.defaultBlockState());
        setBlock(x + 7, y + 11, z + 10, Blocks.AIR.defaultBlockState());
        setBlock(x + 8, y + 11, z + 10, Blocks.AIR.defaultBlockState());
        setBlock(x + 9, y + 11, z + 10, Blocks.AIR.defaultBlockState());
        setBlock(x + 10, y + 11, z + 10, Blocks.AIR.defaultBlockState());
        setBlock(x + 11, y + 11, z + 10, Blocks.STONE_STAIRS.defaultBlockState().setValue(StairBlock.FACING, Direction.WEST));
        setBlock(x + 12, y + 11, z + 10, Blocks.AIR.defaultBlockState());

        setBlock(x, y + 11, z + 11, Blocks.AIR.defaultBlockState());
        setBlock(x + 1, y + 11, z + 11, COBBLESTONE);
        setBlock(x + 2, y + 11, z + 11, Blocks.TRAPPED_CHEST.defaultBlockState().setValue(ChestBlock.FACING, Direction.WEST));
        setBlock(x + 3, y + 11, z + 11, Blocks.AIR.defaultBlockState());
        setBlock(x + 4, y + 11, z + 11, Blocks.AIR.defaultBlockState());
        setBlock(x + 5, y + 11, z + 11, Blocks.AIR.defaultBlockState());
        setBlock(x + 6, y + 11, z + 11, Blocks.AIR.defaultBlockState());
        setBlock(x + 7, y + 11, z + 11, Blocks.AIR.defaultBlockState());
        setBlock(x + 8, y + 11, z + 11, Blocks.AIR.defaultBlockState());
        setBlock(x + 9, y + 11, z + 11, Blocks.AIR.defaultBlockState());
        setBlock(x + 10, y + 11, z + 11, Blocks.AIR.defaultBlockState());
        setBlock(x + 11, y + 11, z + 11, COBBLESTONE);
        setBlock(x + 12, y + 11, z + 11, Blocks.AIR.defaultBlockState());

        setBlock(x, y + 11, z + 12, Blocks.AIR.defaultBlockState());
        setBlock(x + 1, y + 11, z + 12, COBBLESTONE);
        setBlock(x + 2, y + 11, z + 12, Blocks.CHEST.defaultBlockState().setValue(ChestBlock.FACING, Direction.WEST));
        setBlock(x + 3, y + 11, z + 12, Blocks.AIR.defaultBlockState());
        setBlock(x + 4, y + 11, z + 12, Blocks.AIR.defaultBlockState());
        setBlock(x + 5, y + 11, z + 12, Blocks.AIR.defaultBlockState());
        setBlock(x + 6, y + 11, z + 12, Blocks.AIR.defaultBlockState());
        setBlock(x + 7, y + 11, z + 12, Blocks.AIR.defaultBlockState());
        setBlock(x + 8, y + 11, z + 12, Blocks.AIR.defaultBlockState());
        setBlock(x + 9, y + 11, z + 12, Blocks.AIR.defaultBlockState());
        setBlock(x + 10, y + 11, z + 12, Blocks.AIR.defaultBlockState());
        setBlock(x + 11, y + 11, z + 12, COBBLESTONE);
        setBlock(x + 12, y + 11, z + 12, Blocks.AIR.defaultBlockState());

        setBlock(x, y + 11, z + 13, Blocks.AIR.defaultBlockState());
        setBlock(x + 1, y + 11, z + 13, COBBLESTONE);
        setBlock(x + 2, y + 11, z + 13, COBBLESTONE);
        setBlock(x + 3, y + 11, z + 13, COBBLESTONE);
        setBlock(x + 4, y + 11, z + 13, COBBLESTONE);
        setBlock(x + 5, y + 11, z + 13, Blocks.AIR.defaultBlockState());
        setBlock(x + 6, y + 11, z + 13, Blocks.GLASS.defaultBlockState());
        setBlock(x + 7, y + 11, z + 13, Blocks.AIR.defaultBlockState());
        setBlock(x + 8, y + 11, z + 13, COBBLESTONE);
        setBlock(x + 9, y + 11, z + 13, Blocks.STONE_STAIRS.defaultBlockState().setValue(StairBlock.FACING, Direction.EAST));
        setBlock(x + 10, y + 11, z + 13, COBBLESTONE);
        setBlock(x + 11, y + 11, z + 13, COBBLESTONE);
        setBlock(x + 12, y + 11, z + 13, Blocks.AIR.defaultBlockState());

        setBlock(x + 1, y + 11, z + 14, Blocks.AIR.defaultBlockState());
        setBlock(x + 2, y + 11, z + 14, Blocks.AIR.defaultBlockState());
        setBlock(x + 3, y + 11, z + 14, Blocks.AIR.defaultBlockState());
        setBlock(x + 4, y + 11, z + 14, Blocks.AIR.defaultBlockState());
